Workbook

Sheet Master
E1: Product | F1: SWORD | G1: SWORD | H1: SWORD | I1: TEDS | J1: TEDS | K1: TEDS | L1: SPEAR | M1: SPEAR | N1: SPEAR | O1: InformTN | P1: InformTN | Q1: InformTN | R1: Accountability | S1: Accountability | T1: Accountability | U1: ECEDS | V1: ECEDS | W1: ECEDS | X1: URS | Y1: URS | Z1: URS | AA1: CCR | AB1: CCR | AC1: CCR | AD1: CCMS | AE1: CCMS | AF1: CCMS | AG1: TNSD | AH1: TNSD | AI1: TNSD | AJ1: TN Portfolio | AK1: TN Portfolio | AL1: TN Portfolio | AM1: School Nutrition | AN1: School Nutrition | AO1: School Nutrition | AP1: TN TAN | AQ1: TN TAN | AR1: TN TAN | AS1: OAT/BFAC | AT1: OAT/BFAC | AU1: OAT/BFAC | AV1: P20 (CEDS, CCWIS) | AW1: P20 (CEDS, CCWIS) | AX1: P20 (CEDS, CCWIS) | AY1: ePlan | AZ1: ePlan | BA1: ePlan | BB1: Enterprise Reporting | BC1: Enterprise Reporting | BD1: Enterprise Reporting | BE1: EPSO | BF1: EPSO | BG1: EPSO | BH1: FutureReady | BI1: FutureReady | BJ1: FutureReady | BK1: Assessment | BL1: Assessment | BM1: Assessment | BN1: TN Pulse | BO1: TN Pulse | BP1: TN Pulse | BQ1: TN Atlas | BR1: TN Atlas | BS1: TN Atlas | BT1: TN Compass | BU1: TN Compass | BV1: TN Compass | BW1: Core Infrastructure | BX1: Core Infrastructure | BY1: Core Infrastructure | BZ1: Cohort | CA1: Cohort | CB1: Cohort | CC1: CSH Survey | CD1: CSH Survey | CE1: CSH Survey | CF1: Totals | CG1: Totals | CH1: Totals
A2: Role | B2: Hire Type | C2: Contractor Name | D2: bill rate | F2: Net New | G2: Enhance Existing | H2: Maintenance | I2: Net New | J2: Enhance Existing | K2: Maintenance | L2: Net New | M2: Enhance Existing | N2: Maintenance | O2: Net New | P2: Enhance Existing | Q2: Maintenance | R2: Net New | S2: Enhance Existing | T2: Maintenance | U2: Net New | V2: Enhance Existing | W2: Maintenance | X2: Net New | Y2: Enhance Existing | Z2: Maintenance | AA2: Net New | AB2: Enhance Existing | AC2: Maintenance | AD2: Net New | AE2: Enhance Existing | AF2: Maintenance | AG2: Net New | AH2: Enhance Existing | AI2: Maintenance | AJ2: Net New | AK2: Enhance Existing | AL2: Maintenance | AM2: Net New | AN2: Enhance Existing | AO2: Maintenance | AP2: Net New | AQ2: Enhance Existing | AR2: Maintenance | AS2: Net New | AT2: Enhance Existing | AU2: Maintenance | AV2: Net New | AW2: Enhance Existing | AX2: Maintenance | AY2: Net New | AZ2: Enhance Existing | BA2: Maintenance | BB2: Net New | BC2: Enhance Existing | BD2: Maintenance | BE2: Net New | BF2: Enhance Existing | BG2: Maintenance | BH2: Net New | BI2: Enhance Existing | BJ2: Maintenance | BK2: Net New | BL2: Enhance Existing | BM2: Maintenance | BN2: Net New | BO2: Enhance Existing | BP2: Maintenance | BQ2: Net New | BR2: Enhance Existing | BS2: Maintenance | BT2: Net New | BU2: Enhance Existing | BV2: Maintenance | BW2: Net New | BX2: Enhance Existing | BY2: Maintenance | BZ2: Net New | CA2: Enhance Existing | CB2: Maintenance | CC2: Net New | CD2: Enhance Existing | CE2: Maintenance | CF2: Net New Hours | CG2: Enhance Existing Hours | CH2: Maintenance Hours
A3: Sr. Dev | B3: Contractor | C3: Steven McKee | D3: 148.125 | F3: ='July 25'!D3 + 'August 25'!D3 +'Sept 25'!D3 + 'Oct 25'!D3 + 'Nov 25'!D3+ 'Dec 25'!D3 +'Jan 26'!D3+'Feb 26'!D3+'March 26'!D3+'April 26'!D3+'May 26'!D3+'June 26'!D3 -> 0 | G3: ='July 25'!E3 + 'August 25'!E3 +'Sept 25'!E3 + 'Oct 25'!E3 + 'Nov 25'!E3+ 'Dec 25'!E3 +'Jan 26'!E3+'Feb 26'!E3+'March 26'!E3+'April 26'!E3+'May 26'!E3+'June 26'!E3 -> 0 | H3: ='July 25'!F3 + 'August 25'!F3 +'Sept 25'!F3 + 'Oct 25'!F3 + 'Nov 25'!F3+ 'Dec 25'!F3 +'Jan 26'!F3+'Feb 26'!F3+'March 26'!F3+'April 26'!F3+'May 26'!F3+'June 26'!F3 -> 0 | I3: ='July 25'!G3 + 'August 25'!G3 +'Sept 25'!G3 + 'Oct 25'!G3 + 'Nov 25'!G3+ 'Dec 25'!G3 +'Jan 26'!G3+'Feb 26'!G3+'March 26'!G3+'April 26'!G3+'May 26'!G3+'June 26'!G3 -> 1440 | J3: ='July 25'!H3 + 'August 25'!H3 +'Sept 25'!H3 + 'Oct 25'!H3 + 'Nov 25'!H3+ 'Dec 25'!H3 +'Jan 26'!H3+'Feb 26'!H3+'March 26'!H3+'April 26'!H3+'May 26'!H3+'June 26'!H3 -> 0 | K3: ='July 25'!I3 + 'August 25'!I3 +'Sept 25'!I3 + 'Oct 25'!I3 + 'Nov 25'!I3+ 'Dec 25'!I3 +'Jan 26'!I3+'Feb 26'!I3+'March 26'!I3+'April 26'!I3+'May 26'!I3+'June 26'!I3 -> 0 | L3: ='July 25'!J3 + 'August 25'!J3 +'Sept 25'!J3 + 'Oct 25'!J3 + 'Nov 25'!J3+ 'Dec 25'!J3 +'Jan 26'!J3+'Feb 26'!J3+'March 26'!J3+'April 26'!J3+'May 26'!J3+'June 26'!J3 -> 0 | M3: ='July 25'!K3 + 'August 25'!K3 +'Sept 25'!K3 + 'Oct 25'!K3 + 'Nov 25'!K3+ 'Dec 25'!K3 +'Jan 26'!K3+'Feb 26'!K3+'March 26'!K3+'April 26'!K3+'May 26'!K3+'June 26'!K3 -> 0 | ... CE3: ='July 25'!CC3 + 'August 25'!CC3 +'Sept 25'!CC3 + 'Oct 25'!CC3 + 'Nov 25'!CC3+ 'Dec 25'!CC3 +'Jan 26'!CC3+'Feb 26'!CC3+'March 26'!CC3+'April 26'!CC3+'May 26'!CC3+'June 26'!CC3 -> 0 | CF3: {=SUMPRODUCT(--(UPPER($F$2:$CE$2)="NET NEW"),$F3:$CE3)} -> 1440 | CG3: =SUMIF($F$2:$CE$2,"Enhance Existing",$F3:$CE3) -> 0 | CH3: =SUMIF($F$2:$CE$2,"Maintenance",$F3:$CE3) -> 0
A4: Dev | B4: Contractor | C4: Pooja | D4: 98.75 | F4: ='July 25'!D4 + 'August 25'!D4 +'Sept 25'!D4 + 'Oct 25'!D4 + 'Nov 25'!D4+ 'Dec 25'!D4 +'Jan 26'!D4+'Feb 26'!D4+'March 26'!D4+'April 26'!D4+'May 26'!D4+'June 26'!D4 -> 0 | G4: ='July 25'!E4 + 'August 25'!E4 +'Sept 25'!E4 + 'Oct 25'!E4 + 'Nov 25'!E4+ 'Dec 25'!E4 +'Jan 26'!E4+'Feb 26'!E4+'March 26'!E4+'April 26'!E4+'May 26'!E4+'June 26'!E4 -> 0 | H4: ='July 25'!F4 + 'August 25'!F4 +'Sept 25'!F4 + 'Oct 25'!F4 + 'Nov 25'!F4+ 'Dec 25'!F4 +'Jan 26'!F4+'Feb 26'!F4+'March 26'!F4+'April 26'!F4+'May 26'!F4+'June 26'!F4 -> 0 | I4: ='July 25'!G4 + 'August 25'!G4 +'Sept 25'!G4 + 'Oct 25'!G4 + 'Nov 25'!G4+ 'Dec 25'!G4 +'Jan 26'!G4+'Feb 26'!G4+'March 26'!G4+'April 26'!G4+'May 26'!G4+'June 26'!G4 -> 0 | J4: ='July 25'!H4 + 'August 25'!H4 +'Sept 25'!H4 + 'Oct 25'!H4 + 'Nov 25'!H4+ 'Dec 25'!H4 +'Jan 26'!H4+'Feb 26'!H4+'March 26'!H4+'April 26'!H4+'May 26'!H4+'June 26'!H4 -> 0 | K4: ='July 25'!I4 + 'August 25'!I4 +'Sept 25'!I4 + 'Oct 25'!I4 + 'Nov 25'!I4+ 'Dec 25'!I4 +'Jan 26'!I4+'Feb 26'!I4+'March 26'!I4+'April 26'!I4+'May 26'!I4+'June 26'!I4 -> 0 | L4: ='July 25'!J4 + 'August 25'!J4 +'Sept 25'!J4 + 'Oct 25'!J4 + 'Nov 25'!J4+ 'Dec 25'!J4 +'Jan 26'!J4+'Feb 26'!J4+'March 26'!J4+'April 26'!J4+'May 26'!J4+'June 26'!J4 -> 0 | M4: ='July 25'!K4 + 'August 25'!K4 +'Sept 25'!K4 + 'Oct 25'!K4 + 'Nov 25'!K4+ 'Dec 25'!K4 +'Jan 26'!K4+'Feb 26'!K4+'March 26'!K4+'April 26'!K4+'May 26'!K4+'June 26'!K4 -> 0 | ... CE4: ='July 25'!CC4 + 'August 25'!CC4 +'Sept 25'!CC4 + 'Oct 25'!CC4 + 'Nov 25'!CC4+ 'Dec 25'!CC4 +'Jan 26'!CC4+'Feb 26'!CC4+'March 26'!CC4+'April 26'!CC4+'May 26'!CC4+'June 26'!CC4 -> 0 | CF4: {=SUMPRODUCT(--(UPPER($F$2:$CE$2)="NET NEW"),$F4:$CE4)} -> 0 | CG4: =SUMIF($F$2:$CE$2,"Enhance Existing",$F4:$CE4) -> 656 | CH4: =SUMIF($F$2:$CE$2,"Maintenance",$F4:$CE4) -> 664
A5: Sr. Dev | B5: FTE | C5: Tony | F5: ='July 25'!D5 + 'August 25'!D5 +'Sept 25'!D5 + 'Oct 25'!D5 + 'Nov 25'!D5+ 'Dec 25'!D5 +'Jan 26'!D5+'Feb 26'!D5+'March 26'!D5+'April 26'!D5+'May 26'!D5+'June 26'!D5 -> 0 | G5: ='July 25'!E5 + 'August 25'!E5 +'Sept 25'!E5 + 'Oct 25'!E5 + 'Nov 25'!E5+ 'Dec 25'!E5 +'Jan 26'!E5+'Feb 26'!E5+'March 26'!E5+'April 26'!E5+'May 26'!E5+'June 26'!E5 -> 0 | H5: ='July 25'!F5 + 'August 25'!F5 +'Sept 25'!F5 + 'Oct 25'!F5 + 'Nov 25'!F5+ 'Dec 25'!F5 +'Jan 26'!F5+'Feb 26'!F5+'March 26'!F5+'April 26'!F5+'May 26'!F5+'June 26'!F5 -> 0 | I5: ='July 25'!G5 + 'August 25'!G5 +'Sept 25'!G5 + 'Oct 25'!G5 + 'Nov 25'!G5+ 'Dec 25'!G5 +'Jan 26'!G5+'Feb 26'!G5+'March 26'!G5+'April 26'!G5+'May 26'!G5+'June 26'!G5 -> 1440 | J5: ='July 25'!H5 + 'August 25'!H5 +'Sept 25'!H5 + 'Oct 25'!H5 + 'Nov 25'!H5+ 'Dec 25'!H5 +'Jan 26'!H5+'Feb 26'!H5+'March 26'!H5+'April 26'!H5+'May 26'!H5+'June 26'!H5 -> 0 | K5: ='July 25'!I5 + 'August 25'!I5 +'Sept 25'!I5 + 'Oct 25'!I5 + 'Nov 25'!I5+ 'Dec 25'!I5 +'Jan 26'!I5+'Feb 26'!I5+'March 26'!I5+'April 26'!I5+'May 26'!I5+'June 26'!I5 -> 0 | L5: ='July 25'!J5 + 'August 25'!J5 +'Sept 25'!J5 + 'Oct 25'!J5 + 'Nov 25'!J5+ 'Dec 25'!J5 +'Jan 26'!J5+'Feb 26'!J5+'March 26'!J5+'April 26'!J5+'May 26'!J5+'June 26'!J5 -> 0 | M5: ='July 25'!K5 + 'August 25'!K5 +'Sept 25'!K5 + 'Oct 25'!K5 + 'Nov 25'!K5+ 'Dec 25'!K5 +'Jan 26'!K5+'Feb 26'!K5+'March 26'!K5+'April 26'!K5+'May 26'!K5+'June 26'!K5 -> 0 | ... CE5: ='July 25'!CC5 + 'August 25'!CC5 +'Sept 25'!CC5 + 'Oct 25'!CC5 + 'Nov 25'!CC5+ 'Dec 25'!CC5 +'Jan 26'!CC5+'Feb 26'!CC5+'March 26'!CC5+'April 26'!CC5+'May 26'!CC5+'June 26'!CC5 -> 0 | CF5: {=SUMPRODUCT(--(UPPER($F$2:$CE$2)="NET NEW"),$F5:$CE5)} -> 1440 | CG5: =SUMIF($F$2:$CE$2,"Enhance Existing",$F5:$CE5) -> 0 | CH5: =SUMIF($F$2:$CE$2,"Maintenance",$F5:$CE5) -> 0
A6: Dev | B6: Contractor | C6: Lalitha | D6: 82 | F6: ='July 25'!D6 + 'August 25'!D6 +'Sept 25'!D6 + 'Oct 25'!D6 + 'Nov 25'!D6+ 'Dec 25'!D6 +'Jan 26'!D6+'Feb 26'!D6+'March 26'!D6+'April 26'!D6+'May 26'!D6+'June 26'!D6 -> 0 | G6: ='July 25'!E6 + 'August 25'!E6 +'Sept 25'!E6 + 'Oct 25'!E6 + 'Nov 25'!E6+ 'Dec 25'!E6 +'Jan 26'!E6+'Feb 26'!E6+'March 26'!E6+'April 26'!E6+'May 26'!E6+'June 26'!E6 -> 0 | H6: ='July 25'!F6 + 'August 25'!F6 +'Sept 25'!F6 + 'Oct 25'!F6 + 'Nov 25'!F6+ 'Dec 25'!F6 +'Jan 26'!F6+'Feb 26'!F6+'March 26'!F6+'April 26'!F6+'May 26'!F6+'June 26'!F6 -> 0 | I6: ='July 25'!G6 + 'August 25'!G6 +'Sept 25'!G6 + 'Oct 25'!G6 + 'Nov 25'!G6+ 'Dec 25'!G6 +'Jan 26'!G6+'Feb 26'!G6+'March 26'!G6+'April 26'!G6+'May 26'!G6+'June 26'!G6 -> 0 | J6: ='July 25'!H6 + 'August 25'!H6 +'Sept 25'!H6 + 'Oct 25'!H6 + 'Nov 25'!H6+ 'Dec 25'!H6 +'Jan 26'!H6+'Feb 26'!H6+'March 26'!H6+'April 26'!H6+'May 26'!H6+'June 26'!H6 -> 0 | K6: ='July 25'!I6 + 'August 25'!I6 +'Sept 25'!I6 + 'Oct 25'!I6 + 'Nov 25'!I6+ 'Dec 25'!I6 +'Jan 26'!I6+'Feb 26'!I6+'March 26'!I6+'April 26'!I6+'May 26'!I6+'June 26'!I6 -> 0 | L6: ='July 25'!J6 + 'August 25'!J6 +'Sept 25'!J6 + 'Oct 25'!J6 + 'Nov 25'!J6+ 'Dec 25'!J6 +'Jan 26'!J6+'Feb 26'!J6+'March 26'!J6+'April 26'!J6+'May 26'!J6+'June 26'!J6 -> 0 | M6: ='July 25'!K6 + 'August 25'!K6 +'Sept 25'!K6 + 'Oct 25'!K6 + 'Nov 25'!K6+ 'Dec 25'!K6 +'Jan 26'!K6+'Feb 26'!K6+'March 26'!K6+'April 26'!K6+'May 26'!K6+'June 26'!K6 -> 0 | ... CE6: ='July 25'!CC6 + 'August 25'!CC6 +'Sept 25'!CC6 + 'Oct 25'!CC6 + 'Nov 25'!CC6+ 'Dec 25'!CC6 +'Jan 26'!CC6+'Feb 26'!CC6+'March 26'!CC6+'April 26'!CC6+'May 26'!CC6+'June 26'!CC6 -> 0 | CF6: {=SUMPRODUCT(--(UPPER($F$2:$CE$2)="NET NEW"),$F6:$CE6)} -> 0 | CG6: =SUMIF($F$2:$CE$2,"Enhance Existing",$F6:$CE6) -> 55 | CH6: =SUMIF($F$2:$CE$2,"Maintenance",$F6:$CE6) -> 1399
A7: Sr. Dev | B7: FTE | C7: Greg Marcum | F7: ='July 25'!D7 + 'August 25'!D7 +'Sept 25'!D7 + 'Oct 25'!D7 + 'Nov 25'!D7+ 'Dec 25'!D7 +'Jan 26'!D7+'Feb 26'!D7+'March 26'!D7+'April 26'!D7+'May 26'!D7+'June 26'!D7 -> 0 | G7: ='July 25'!E7 + 'August 25'!E7 +'Sept 25'!E7 + 'Oct 25'!E7 + 'Nov 25'!E7+ 'Dec 25'!E7 +'Jan 26'!E7+'Feb 26'!E7+'March 26'!E7+'April 26'!E7+'May 26'!E7+'June 26'!E7 -> 0 | H7: ='July 25'!F7 + 'August 25'!F7 +'Sept 25'!F7 + 'Oct 25'!F7 + 'Nov 25'!F7+ 'Dec 25'!F7 +'Jan 26'!F7+'Feb 26'!F7+'March 26'!F7+'April 26'!F7+'May 26'!F7+'June 26'!F7 -> 18 | I7: ='July 25'!G7 + 'August 25'!G7 +'Sept 25'!G7 + 'Oct 25'!G7 + 'Nov 25'!G7+ 'Dec 25'!G7 +'Jan 26'!G7+'Feb 26'!G7+'March 26'!G7+'April 26'!G7+'May 26'!G7+'June 26'!G7 -> 0 | J7: ='July 25'!H7 + 'August 25'!H7 +'Sept 25'!H7 + 'Oct 25'!H7 + 'Nov 25'!H7+ 'Dec 25'!H7 +'Jan 26'!H7+'Feb 26'!H7+'March 26'!H7+'April 26'!H7+'May 26'!H7+'June 26'!H7 -> 0 | K7: ='July 25'!I7 + 'August 25'!I7 +'Sept 25'!I7 + 'Oct 25'!I7 + 'Nov 25'!I7+ 'Dec 25'!I7 +'Jan 26'!I7+'Feb 26'!I7+'March 26'!I7+'April 26'!I7+'May 26'!I7+'June 26'!I7 -> 113 | L7: ='July 25'!J7 + 'August 25'!J7 +'Sept 25'!J7 + 'Oct 25'!J7 + 'Nov 25'!J7+ 'Dec 25'!J7 +'Jan 26'!J7+'Feb 26'!J7+'March 26'!J7+'April 26'!J7+'May 26'!J7+'June 26'!J7 -> 0 | M7: ='July 25'!K7 + 'August 25'!K7 +'Sept 25'!K7 + 'Oct 25'!K7 + 'Nov 25'!K7+ 'Dec 25'!K7 +'Jan 26'!K7+'Feb 26'!K7+'March 26'!K7+'April 26'!K7+'May 26'!K7+'June 26'!K7 -> 0 | ... CE7: ='July 25'!CC7 + 'August 25'!CC7 +'Sept 25'!CC7 + 'Oct 25'!CC7 + 'Nov 25'!CC7+ 'Dec 25'!CC7 +'Jan 26'!CC7+'Feb 26'!CC7+'March 26'!CC7+'April 26'!CC7+'May 26'!CC7+'June 26'!CC7 -> 0 | CF7: {=SUMPRODUCT(--(UPPER($F$2:$CE$2)="NET NEW"),$F7:$CE7)} -> 0 | CG7: =SUMIF($F$2:$CE$2,"Enhance Existing",$F7:$CE7) -> 0 | CH7: =SUMIF($F$2:$CE$2,"Maintenance",$F7:$CE7) -> 1325
A8: Dev | B8: FTE | C8: Simrath | F8: ='July 25'!D8 + 'August 25'!D8 +'Sept 25'!D8 + 'Oct 25'!D8 + 'Nov 25'!D8+ 'Dec 25'!D8 +'Jan 26'!D8+'Feb 26'!D8+'March 26'!D8+'April 26'!D8+'May 26'!D8+'June 26'!D8 -> 0 | G8: ='July 25'!E8 + 'August 25'!E8 +'Sept 25'!E8 + 'Oct 25'!E8 + 'Nov 25'!E8+ 'Dec 25'!E8 +'Jan 26'!E8+'Feb 26'!E8+'March 26'!E8+'April 26'!E8+'May 26'!E8+'June 26'!E8 -> 0 | H8: ='July 25'!F8 + 'August 25'!F8 +'Sept 25'!F8 + 'Oct 25'!F8 + 'Nov 25'!F8+ 'Dec 25'!F8 +'Jan 26'!F8+'Feb 26'!F8+'March 26'!F8+'April 26'!F8+'May 26'!F8+'June 26'!F8 -> 0 | I8: ='July 25'!G8 + 'August 25'!G8 +'Sept 25'!G8 + 'Oct 25'!G8 + 'Nov 25'!G8+ 'Dec 25'!G8 +'Jan 26'!G8+'Feb 26'!G8+'March 26'!G8+'April 26'!G8+'May 26'!G8+'June 26'!G8 -> 0 | J8: ='July 25'!H8 + 'August 25'!H8 +'Sept 25'!H8 + 'Oct 25'!H8 + 'Nov 25'!H8+ 'Dec 25'!H8 +'Jan 26'!H8+'Feb 26'!H8+'March 26'!H8+'April 26'!H8+'May 26'!H8+'June 26'!H8 -> 0 | K8: ='July 25'!I8 + 'August 25'!I8 +'Sept 25'!I8 + 'Oct 25'!I8 + 'Nov 25'!I8+ 'Dec 25'!I8 +'Jan 26'!I8+'Feb 26'!I8+'March 26'!I8+'April 26'!I8+'May 26'!I8+'June 26'!I8 -> 0 | L8: ='July 25'!J8 + 'August 25'!J8 +'Sept 25'!J8 + 'Oct 25'!J8 + 'Nov 25'!J8+ 'Dec 25'!J8 +'Jan 26'!J8+'Feb 26'!J8+'March 26'!J8+'April 26'!J8+'May 26'!J8+'June 26'!J8 -> 0 | M8: ='July 25'!K8 + 'August 25'!K8 +'Sept 25'!K8 + 'Oct 25'!K8 + 'Nov 25'!K8+ 'Dec 25'!K8 +'Jan 26'!K8+'Feb 26'!K8+'March 26'!K8+'April 26'!K8+'May 26'!K8+'June 26'!K8 -> 0 | ... CE8: ='July 25'!CC8 + 'August 25'!CC8 +'Sept 25'!CC8 + 'Oct 25'!CC8 + 'Nov 25'!CC8+ 'Dec 25'!CC8 +'Jan 26'!CC8+'Feb 26'!CC8+'March 26'!CC8+'April 26'!CC8+'May 26'!CC8+'June 26'!CC8 -> 14 | CF8: {=SUMPRODUCT(--(UPPER($F$2:$CE$2)="NET NEW"),$F8:$CE8)} -> 0 | CG8: =SUMIF($F$2:$CE$2,"Enhance Existing",$F8:$CE8) -> 201 | CH8: =SUMIF($F$2:$CE$2,"Maintenance",$F8:$CE8) -> 1188
A9: Dev | B9: Contractor | C9: Sriram | D9: 85 | F9: ='July 25'!D9 + 'August 25'!D9 +'Sept 25'!D9 + 'Oct 25'!D9 + 'Nov 25'!D9+ 'Dec 25'!D9 +'Jan 26'!D9+'Feb 26'!D9+'March 26'!D9+'April 26'!D9+'May 26'!D9+'June 26'!D9 -> 0 | G9: ='July 25'!E9 + 'August 25'!E9 +'Sept 25'!E9 + 'Oct 25'!E9 + 'Nov 25'!E9+ 'Dec 25'!E9 +'Jan 26'!E9+'Feb 26'!E9+'March 26'!E9+'April 26'!E9+'May 26'!E9+'June 26'!E9 -> 0 | H9: ='July 25'!F9 + 'August 25'!F9 +'Sept 25'!F9 + 'Oct 25'!F9 + 'Nov 25'!F9+ 'Dec 25'!F9 +'Jan 26'!F9+'Feb 26'!F9+'March 26'!F9+'April 26'!F9+'May 26'!F9+'June 26'!F9 -> 0 | I9: ='July 25'!G9 + 'August 25'!G9 +'Sept 25'!G9 + 'Oct 25'!G9 + 'Nov 25'!G9+ 'Dec 25'!G9 +'Jan 26'!G9+'Feb 26'!G9+'March 26'!G9+'April 26'!G9+'May 26'!G9+'June 26'!G9 -> 0 | J9: ='July 25'!H9 + 'August 25'!H9 +'Sept 25'!H9 + 'Oct 25'!H9 + 'Nov 25'!H9+ 'Dec 25'!H9 +'Jan 26'!H9+'Feb 26'!H9+'March 26'!H9+'April 26'!H9+'May 26'!H9+'June 26'!H9 -> 0 | K9: ='July 25'!I9 + 'August 25'!I9 +'Sept 25'!I9 + 'Oct 25'!I9 + 'Nov 25'!I9+ 'Dec 25'!I9 +'Jan 26'!I9+'Feb 26'!I9+'March 26'!I9+'April 26'!I9+'May 26'!I9+'June 26'!I9 -> 0 | L9: ='July 25'!J9 + 'August 25'!J9 +'Sept 25'!J9 + 'Oct 25'!J9 + 'Nov 25'!J9+ 'Dec 25'!J9 +'Jan 26'!J9+'Feb 26'!J9+'March 26'!J9+'April 26'!J9+'May 26'!J9+'June 26'!J9 -> 0 | M9: ='July 25'!K9 + 'August 25'!K9 +'Sept 25'!K9 + 'Oct 25'!K9 + 'Nov 25'!K9+ 'Dec 25'!K9 +'Jan 26'!K9+'Feb 26'!K9+'March 26'!K9+'April 26'!K9+'May 26'!K9+'June 26'!K9 -> 0 | ... CE9: ='July 25'!CC9 + 'August 25'!CC9 +'Sept 25'!CC9 + 'Oct 25'!CC9 + 'Nov 25'!CC9+ 'Dec 25'!CC9 +'Jan 26'!CC9+'Feb 26'!CC9+'March 26'!CC9+'April 26'!CC9+'May 26'!CC9+'June 26'!CC9 -> 0 | CF9: {=SUMPRODUCT(--(UPPER($F$2:$CE$2)="NET NEW"),$F9:$CE9)} -> 222 | CG9: =SUMIF($F$2:$CE$2,"Enhance Existing",$F9:$CE9) -> 0 | CH9: =SUMIF($F$2:$CE$2,"Maintenance",$F9:$CE9) -> 1174
A10: Dev | B10: FTE | C10: Justin Meshew | F10: ='July 25'!D10 + 'August 25'!D10 +'Sept 25'!D10 + 'Oct 25'!D10 + 'Nov 25'!D10+ 'Dec 25'!D10 +'Jan 26'!D10+'Feb 26'!D10+'March 26'!D10+'April 26'!D10+'May 26'!D10+'June 26'!D10 -> 0 | G10: ='July 25'!E10 + 'August 25'!E10 +'Sept 25'!E10 + 'Oct 25'!E10 + 'Nov 25'!E10+ 'Dec 25'!E10 +'Jan 26'!E10+'Feb 26'!E10+'March 26'!E10+'April 26'!E10+'May 26'!E10+'June 26'!E10 -> 0 | H10: ='July 25'!F10 + 'August 25'!F10 +'Sept 25'!F10 + 'Oct 25'!F10 + 'Nov 25'!F10+ 'Dec 25'!F10 +'Jan 26'!F10+'Feb 26'!F10+'March 26'!F10+'April 26'!F10+'May 26'!F10+'June 26'!F10 -> 0 | I10: ='July 25'!G10 + 'August 25'!G10 +'Sept 25'!G10 + 'Oct 25'!G10 + 'Nov 25'!G10+ 'Dec 25'!G10 +'Jan 26'!G10+'Feb 26'!G10+'March 26'!G10+'April 26'!G10+'May 26'!G10+'June 26'!G10 -> 0 | J10: ='July 25'!H10 + 'August 25'!H10 +'Sept 25'!H10 + 'Oct 25'!H10 + 'Nov 25'!H10+ 'Dec 25'!H10 +'Jan 26'!H10+'Feb 26'!H10+'March 26'!H10+'April 26'!H10+'May 26'!H10+'June 26'!H10 -> 0 | K10: ='July 25'!I10 + 'August 25'!I10 +'Sept 25'!I10 + 'Oct 25'!I10 + 'Nov 25'!I10+ 'Dec 25'!I10 +'Jan 26'!I10+'Feb 26'!I10+'March 26'!I10+'April 26'!I10+'May 26'!I10+'June 26'!I10 -> 0 | L10: ='July 25'!J10 + 'August 25'!J10 +'Sept 25'!J10 + 'Oct 25'!J10 + 'Nov 25'!J10+ 'Dec 25'!J10 +'Jan 26'!J10+'Feb 26'!J10+'March 26'!J10+'April 26'!J10+'May 26'!J10+'June 26'!J10 -> 0 | M10: ='July 25'!K10 + 'August 25'!K10 +'Sept 25'!K10 + 'Oct 25'!K10 + 'Nov 25'!K10+ 'Dec 25'!K10 +'Jan 26'!K10+'Feb 26'!K10+'March 26'!K10+'April 26'!K10+'May 26'!K10+'June 26'!K10 -> 0 | ... CE10: ='July 25'!CC10 + 'August 25'!CC10 +'Sept 25'!CC10 + 'Oct 25'!CC10 + 'Nov 25'!CC10+ 'Dec 25'!CC10 +'Jan 26'!CC10+'Feb 26'!CC10+'March 26'!CC10+'April 26'!CC10+'May 26'!CC10+'June 26'!CC10 -> 68 | CF10: {=SUMPRODUCT(--(UPPER($F$2:$CE$2)="NET NEW"),$F10:$CE10)} -> 0 | CG10: =SUMIF($F$2:$CE$2,"Enhance Existing",$F10:$CE10) -> 259 | CH10: =SUMIF($F$2:$CE$2,"Maintenance",$F10:$CE10) -> 1154
A11: Sr. Dev | B11: FTE | C11: Ryan Dailey | F11: ='July 25'!D11 + 'August 25'!D11 +'Sept 25'!D11 + 'Oct 25'!D11 + 'Nov 25'!D11+ 'Dec 25'!D11 +'Jan 26'!D11+'Feb 26'!D11+'March 26'!D11+'April 26'!D11+'May 26'!D11+'June 26'!D11 -> 0 | G11: ='July 25'!E11 + 'August 25'!E11 +'Sept 25'!E11 + 'Oct 25'!E11 + 'Nov 25'!E11+ 'Dec 25'!E11 +'Jan 26'!E11+'Feb 26'!E11+'March 26'!E11+'April 26'!E11+'May 26'!E11+'June 26'!E11 -> 0 | H11: ='July 25'!F11 + 'August 25'!F11 +'Sept 25'!F11 + 'Oct 25'!F11 + 'Nov 25'!F11+ 'Dec 25'!F11 +'Jan 26'!F11+'Feb 26'!F11+'March 26'!F11+'April 26'!F11+'May 26'!F11+'June 26'!F11 -> 0 | I11: ='July 25'!G11 + 'August 25'!G11 +'Sept 25'!G11 + 'Oct 25'!G11 + 'Nov 25'!G11+ 'Dec 25'!G11 +'Jan 26'!G11+'Feb 26'!G11+'March 26'!G11+'April 26'!G11+'May 26'!G11+'June 26'!G11 -> 0 | J11: ='July 25'!H11 + 'August 25'!H11 +'Sept 25'!H11 + 'Oct 25'!H11 + 'Nov 25'!H11+ 'Dec 25'!H11 +'Jan 26'!H11+'Feb 26'!H11+'March 26'!H11+'April 26'!H11+'May 26'!H11+'June 26'!H11 -> 0 | K11: ='July 25'!I11 + 'August 25'!I11 +'Sept 25'!I11 + 'Oct 25'!I11 + 'Nov 25'!I11+ 'Dec 25'!I11 +'Jan 26'!I11+'Feb 26'!I11+'March 26'!I11+'April 26'!I11+'May 26'!I11+'June 26'!I11 -> 0 | L11: ='July 25'!J11 + 'August 25'!J11 +'Sept 25'!J11 + 'Oct 25'!J11 + 'Nov 25'!J11+ 'Dec 25'!J11 +'Jan 26'!J11+'Feb 26'!J11+'March 26'!J11+'April 26'!J11+'May 26'!J11+'June 26'!J11 -> 0 | M11: ='July 25'!K11 + 'August 25'!K11 +'Sept 25'!K11 + 'Oct 25'!K11 + 'Nov 25'!K11+ 'Dec 25'!K11 +'Jan 26'!K11+'Feb 26'!K11+'March 26'!K11+'April 26'!K11+'May 26'!K11+'June 26'!K11 -> 0 | ... CE11: ='July 25'!CC11 + 'August 25'!CC11 +'Sept 25'!CC11 + 'Oct 25'!CC11 + 'Nov 25'!CC11+ 'Dec 25'!CC11 +'Jan 26'!CC11+'Feb 26'!CC11+'March 26'!CC11+'April 26'!CC11+'May 26'!CC11+'June 26'!CC11 -> 0 | CF11: {=SUMPRODUCT(--(UPPER($F$2:$CE$2)="NET NEW"),$F11:$CE11)} -> 0 | CG11: =SUMIF($F$2:$CE$2,"Enhance Existing",$F11:$CE11) -> 0 | CH11: =SUMIF($F$2:$CE$2,"Maintenance",$F11:$CE11) -> 1410
A12: Dev | B12: Contractor | C12: Dean Bowles | D12: 90 | F12: ='July 25'!D12 + 'August 25'!D12 +'Sept 25'!D12 + 'Oct 25'!D12 + 'Nov 25'!D12+ 'Dec 25'!D12 +'Jan 26'!D12+'Feb 26'!D12+'March 26'!D12+'April 26'!D12+'May 26'!D12+'June 26'!D12 -> 0 | G12: ='July 25'!E12 + 'August 25'!E12 +'Sept 25'!E12 + 'Oct 25'!E12 + 'Nov 25'!E12+ 'Dec 25'!E12 +'Jan 26'!E12+'Feb 26'!E12+'March 26'!E12+'April 26'!E12+'May 26'!E12+'June 26'!E12 -> 0 | H12: ='July 25'!F12 + 'August 25'!F12 +'Sept 25'!F12 + 'Oct 25'!F12 + 'Nov 25'!F12+ 'Dec 25'!F12 +'Jan 26'!F12+'Feb 26'!F12+'March 26'!F12+'April 26'!F12+'May 26'!F12+'June 26'!F12 -> 0 | I12: ='July 25'!G12 + 'August 25'!G12 +'Sept 25'!G12 + 'Oct 25'!G12 + 'Nov 25'!G12+ 'Dec 25'!G12 +'Jan 26'!G12+'Feb 26'!G12+'March 26'!G12+'April 26'!G12+'May 26'!G12+'June 26'!G12 -> 0 | J12: ='July 25'!H12 + 'August 25'!H12 +'Sept 25'!H12 + 'Oct 25'!H12 + 'Nov 25'!H12+ 'Dec 25'!H12 +'Jan 26'!H12+'Feb 26'!H12+'March 26'!H12+'April 26'!H12+'May 26'!H12+'June 26'!H12 -> 0 | K12: ='July 25'!I12 + 'August 25'!I12 +'Sept 25'!I12 + 'Oct 25'!I12 + 'Nov 25'!I12+ 'Dec 25'!I12 +'Jan 26'!I12+'Feb 26'!I12+'March 26'!I12+'April 26'!I12+'May 26'!I12+'June 26'!I12 -> 0 | L12: ='July 25'!J12 + 'August 25'!J12 +'Sept 25'!J12 + 'Oct 25'!J12 + 'Nov 25'!J12+ 'Dec 25'!J12 +'Jan 26'!J12+'Feb 26'!J12+'March 26'!J12+'April 26'!J12+'May 26'!J12+'June 26'!J12 -> 0 | M12: ='July 25'!K12 + 'August 25'!K12 +'Sept 25'!K12 + 'Oct 25'!K12 + 'Nov 25'!K12+ 'Dec 25'!K12 +'Jan 26'!K12+'Feb 26'!K12+'March 26'!K12+'April 26'!K12+'May 26'!K12+'June 26'!K12 -> 0 | ... CE12: ='July 25'!CC12 + 'August 25'!CC12 +'Sept 25'!CC12 + 'Oct 25'!CC12 + 'Nov 25'!CC12+ 'Dec 25'!CC12 +'Jan 26'!CC12+'Feb 26'!CC12+'March 26'!CC12+'April 26'!CC12+'May 26'!CC12+'June 26'!CC12 -> 0 | CF12: {=SUMPRODUCT(--(UPPER($F$2:$CE$2)="NET NEW"),$F12:$CE12)} -> 718 | CG12: =SUMIF($F$2:$CE$2,"Enhance Existing",$F12:$CE12) -> 0 | CH12: =SUMIF($F$2:$CE$2,"Maintenance",$F12:$CE12) -> 513
A13: Sr. Dev | B13: Contractor | C13: Donnie | D13: 146.15 | F13: ='July 25'!D13 + 'August 25'!D13 +'Sept 25'!D13 + 'Oct 25'!D13 + 'Nov 25'!D13+ 'Dec 25'!D13 +'Jan 26'!D13+'Feb 26'!D13+'March 26'!D13+'April 26'!D13+'May 26'!D13+'June 26'!D13 -> 1000 | G13: ='July 25'!E13 + 'August 25'!E13 +'Sept 25'!E13 + 'Oct 25'!E13 + 'Nov 25'!E13+ 'Dec 25'!E13 +'Jan 26'!E13+'Feb 26'!E13+'March 26'!E13+'April 26'!E13+'May 26'!E13+'June 26'!E13 -> 0 | H13: ='July 25'!F13 + 'August 25'!F13 +'Sept 25'!F13 + 'Oct 25'!F13 + 'Nov 25'!F13+ 'Dec 25'!F13 +'Jan 26'!F13+'Feb 26'!F13+'March 26'!F13+'April 26'!F13+'May 26'!F13+'June 26'!F13 -> 440 | I13: ='July 25'!G13 + 'August 25'!G13 +'Sept 25'!G13 + 'Oct 25'!G13 + 'Nov 25'!G13+ 'Dec 25'!G13 +'Jan 26'!G13+'Feb 26'!G13+'March 26'!G13+'April 26'!G13+'May 26'!G13+'June 26'!G13 -> 0 | J13: ='July 25'!H13 + 'August 25'!H13 +'Sept 25'!H13 + 'Oct 25'!H13 + 'Nov 25'!H13+ 'Dec 25'!H13 +'Jan 26'!H13+'Feb 26'!H13+'March 26'!H13+'April 26'!H13+'May 26'!H13+'June 26'!H13 -> 0 | K13: ='July 25'!I13 + 'August 25'!I13 +'Sept 25'!I13 + 'Oct 25'!I13 + 'Nov 25'!I13+ 'Dec 25'!I13 +'Jan 26'!I13+'Feb 26'!I13+'March 26'!I13+'April 26'!I13+'May 26'!I13+'June 26'!I13 -> 0 | L13: ='July 25'!J13 + 'August 25'!J13 +'Sept 25'!J13 + 'Oct 25'!J13 + 'Nov 25'!J13+ 'Dec 25'!J13 +'Jan 26'!J13+'Feb 26'!J13+'March 26'!J13+'April 26'!J13+'May 26'!J13+'June 26'!J13 -> 0 | M13: ='July 25'!K13 + 'August 25'!K13 +'Sept 25'!K13 + 'Oct 25'!K13 + 'Nov 25'!K13+ 'Dec 25'!K13 +'Jan 26'!K13+'Feb 26'!K13+'March 26'!K13+'April 26'!K13+'May 26'!K13+'June 26'!K13 -> 0 | ... CE13: ='July 25'!CC13 + 'August 25'!CC13 +'Sept 25'!CC13 + 'Oct 25'!CC13 + 'Nov 25'!CC13+ 'Dec 25'!CC13 +'Jan 26'!CC13+'Feb 26'!CC13+'March 26'!CC13+'April 26'!CC13+'May 26'!CC13+'June 26'!CC13 -> 0 | CF13: {=SUMPRODUCT(--(UPPER($F$2:$CE$2)="NET NEW"),$F13:$CE13)} -> 1000 | CG13: =SUMIF($F$2:$CE$2,"Enhance Existing",$F13:$CE13) -> 0 | CH13: =SUMIF($F$2:$CE$2,"Maintenance",$F13:$CE13) -> 440
A14: Sr. Dev | B14: Contractor | C14: Mark | D14: 148.125 | F14: ='July 25'!D14 + 'August 25'!D14 +'Sept 25'!D14 + 'Oct 25'!D14 + 'Nov 25'!D14+ 'Dec 25'!D14 +'Jan 26'!D14+'Feb 26'!D14+'March 26'!D14+'April 26'!D14+'May 26'!D14+'June 26'!D14 -> 1440 | G14: ='July 25'!E14 + 'August 25'!E14 +'Sept 25'!E14 + 'Oct 25'!E14 + 'Nov 25'!E14+ 'Dec 25'!E14 +'Jan 26'!E14+'Feb 26'!E14+'March 26'!E14+'April 26'!E14+'May 26'!E14+'June 26'!E14 -> 0 | H14: ='July 25'!F14 + 'August 25'!F14 +'Sept 25'!F14 + 'Oct 25'!F14 + 'Nov 25'!F14+ 'Dec 25'!F14 +'Jan 26'!F14+'Feb 26'!F14+'March 26'!F14+'April 26'!F14+'May 26'!F14+'June 26'!F14 -> 0 | I14: ='July 25'!G14 + 'August 25'!G14 +'Sept 25'!G14 + 'Oct 25'!G14 + 'Nov 25'!G14+ 'Dec 25'!G14 +'Jan 26'!G14+'Feb 26'!G14+'March 26'!G14+'April 26'!G14+'May 26'!G14+'June 26'!G14 -> 0 | J14: ='July 25'!H14 + 'August 25'!H14 +'Sept 25'!H14 + 'Oct 25'!H14 + 'Nov 25'!H14+ 'Dec 25'!H14 +'Jan 26'!H14+'Feb 26'!H14+'March 26'!H14+'April 26'!H14+'May 26'!H14+'June 26'!H14 -> 0 | K14: ='July 25'!I14 + 'August 25'!I14 +'Sept 25'!I14 + 'Oct 25'!I14 + 'Nov 25'!I14+ 'Dec 25'!I14 +'Jan 26'!I14+'Feb 26'!I14+'March 26'!I14+'April 26'!I14+'May 26'!I14+'June 26'!I14 -> 0 | L14: ='July 25'!J14 + 'August 25'!J14 +'Sept 25'!J14 + 'Oct 25'!J14 + 'Nov 25'!J14+ 'Dec 25'!J14 +'Jan 26'!J14+'Feb 26'!J14+'March 26'!J14+'April 26'!J14+'May 26'!J14+'June 26'!J14 -> 0 | M14: ='July 25'!K14 + 'August 25'!K14 +'Sept 25'!K14 + 'Oct 25'!K14 + 'Nov 25'!K14+ 'Dec 25'!K14 +'Jan 26'!K14+'Feb 26'!K14+'March 26'!K14+'April 26'!K14+'May 26'!K14+'June 26'!K14 -> 0 | ... CE14: ='July 25'!CC14 + 'August 25'!CC14 +'Sept 25'!CC14 + 'Oct 25'!CC14 + 'Nov 25'!CC14+ 'Dec 25'!CC14 +'Jan 26'!CC14+'Feb 26'!CC14+'March 26'!CC14+'April 26'!CC14+'May 26'!CC14+'June 26'!CC14 -> 0 | CF14: {=SUMPRODUCT(--(UPPER($F$2:$CE$2)="NET NEW"),$F14:$CE14)} -> 1440 | CG14: =SUMIF($F$2:$CE$2,"Enhance Existing",$F14:$CE14) -> 0 | CH14: =SUMIF($F$2:$CE$2,"Maintenance",$F14:$CE14) -> 0
A15: Dev | B15: Contractor | C15: Kasey Goodwin | D15: 30 | F15: ='July 25'!D15 + 'August 25'!D15 +'Sept 25'!D15 + 'Oct 25'!D15 + 'Nov 25'!D15+ 'Dec 25'!D15 +'Jan 26'!D15+'Feb 26'!D15+'March 26'!D15+'April 26'!D15+'May 26'!D15+'June 26'!D15 -> 0 | G15: ='July 25'!E15 + 'August 25'!E15 +'Sept 25'!E15 + 'Oct 25'!E15 + 'Nov 25'!E15+ 'Dec 25'!E15 +'Jan 26'!E15+'Feb 26'!E15+'March 26'!E15+'April 26'!E15+'May 26'!E15+'June 26'!E15 -> 0 | H15: ='July 25'!F15 + 'August 25'!F15 +'Sept 25'!F15 + 'Oct 25'!F15 + 'Nov 25'!F15+ 'Dec 25'!F15 +'Jan 26'!F15+'Feb 26'!F15+'March 26'!F15+'April 26'!F15+'May 26'!F15+'June 26'!F15 -> 0 | I15: ='July 25'!G15 + 'August 25'!G15 +'Sept 25'!G15 + 'Oct 25'!G15 + 'Nov 25'!G15+ 'Dec 25'!G15 +'Jan 26'!G15+'Feb 26'!G15+'March 26'!G15+'April 26'!G15+'May 26'!G15+'June 26'!G15 -> 0 | J15: ='July 25'!H15 + 'August 25'!H15 +'Sept 25'!H15 + 'Oct 25'!H15 + 'Nov 25'!H15+ 'Dec 25'!H15 +'Jan 26'!H15+'Feb 26'!H15+'March 26'!H15+'April 26'!H15+'May 26'!H15+'June 26'!H15 -> 0 | K15: ='July 25'!I15 + 'August 25'!I15 +'Sept 25'!I15 + 'Oct 25'!I15 + 'Nov 25'!I15+ 'Dec 25'!I15 +'Jan 26'!I15+'Feb 26'!I15+'March 26'!I15+'April 26'!I15+'May 26'!I15+'June 26'!I15 -> 0 | L15: ='July 25'!J15 + 'August 25'!J15 +'Sept 25'!J15 + 'Oct 25'!J15 + 'Nov 25'!J15+ 'Dec 25'!J15 +'Jan 26'!J15+'Feb 26'!J15+'March 26'!J15+'April 26'!J15+'May 26'!J15+'June 26'!J15 -> 0 | M15: ='July 25'!K15 + 'August 25'!K15 +'Sept 25'!K15 + 'Oct 25'!K15 + 'Nov 25'!K15+ 'Dec 25'!K15 +'Jan 26'!K15+'Feb 26'!K15+'March 26'!K15+'April 26'!K15+'May 26'!K15+'June 26'!K15 -> 0 | ... CE15: ='July 25'!CC15 + 'August 25'!CC15 +'Sept 25'!CC15 + 'Oct 25'!CC15 + 'Nov 25'!CC15+ 'Dec 25'!CC15 +'Jan 26'!CC15+'Feb 26'!CC15+'March 26'!CC15+'April 26'!CC15+'May 26'!CC15+'June 26'!CC15 -> 0 | CF15: {=SUMPRODUCT(--(UPPER($F$2:$CE$2)="NET NEW"),$F15:$CE15)} -> 0 | CG15: =SUMIF($F$2:$CE$2,"Enhance Existing",$F15:$CE15) -> 0 | CH15: =SUMIF($F$2:$CE$2,"Maintenance",$F15:$CE15) -> 720
A16: Sr. Dev | B16: Contractor | C16: Greg Brethen | D16: 100 | F16: ='July 25'!D16 + 'August 25'!D16 +'Sept 25'!D16 + 'Oct 25'!D16 + 'Nov 25'!D16+ 'Dec 25'!D16 +'Jan 26'!D16+'Feb 26'!D16+'March 26'!D16+'April 26'!D16+'May 26'!D16+'June 26'!D16 -> 0 | G16: ='July 25'!E16 + 'August 25'!E16 +'Sept 25'!E16 + 'Oct 25'!E16 + 'Nov 25'!E16+ 'Dec 25'!E16 +'Jan 26'!E16+'Feb 26'!E16+'March 26'!E16+'April 26'!E16+'May 26'!E16+'June 26'!E16 -> 0 | H16: ='July 25'!F16 + 'August 25'!F16 +'Sept 25'!F16 + 'Oct 25'!F16 + 'Nov 25'!F16+ 'Dec 25'!F16 +'Jan 26'!F16+'Feb 26'!F16+'March 26'!F16+'April 26'!F16+'May 26'!F16+'June 26'!F16 -> 960 | I16: ='July 25'!G16 + 'August 25'!G16 +'Sept 25'!G16 + 'Oct 25'!G16 + 'Nov 25'!G16+ 'Dec 25'!G16 +'Jan 26'!G16+'Feb 26'!G16+'March 26'!G16+'April 26'!G16+'May 26'!G16+'June 26'!G16 -> 0 | J16: ='July 25'!H16 + 'August 25'!H16 +'Sept 25'!H16 + 'Oct 25'!H16 + 'Nov 25'!H16+ 'Dec 25'!H16 +'Jan 26'!H16+'Feb 26'!H16+'March 26'!H16+'April 26'!H16+'May 26'!H16+'June 26'!H16 -> 0 | K16: ='July 25'!I16 + 'August 25'!I16 +'Sept 25'!I16 + 'Oct 25'!I16 + 'Nov 25'!I16+ 'Dec 25'!I16 +'Jan 26'!I16+'Feb 26'!I16+'March 26'!I16+'April 26'!I16+'May 26'!I16+'June 26'!I16 -> 0 | L16: ='July 25'!J16 + 'August 25'!J16 +'Sept 25'!J16 + 'Oct 25'!J16 + 'Nov 25'!J16+ 'Dec 25'!J16 +'Jan 26'!J16+'Feb 26'!J16+'March 26'!J16+'April 26'!J16+'May 26'!J16+'June 26'!J16 -> 0 | M16: ='July 25'!K16 + 'August 25'!K16 +'Sept 25'!K16 + 'Oct 25'!K16 + 'Nov 25'!K16+ 'Dec 25'!K16 +'Jan 26'!K16+'Feb 26'!K16+'March 26'!K16+'April 26'!K16+'May 26'!K16+'June 26'!K16 -> 0 | ... CE16: ='July 25'!CC16 + 'August 25'!CC16 +'Sept 25'!CC16 + 'Oct 25'!CC16 + 'Nov 25'!CC16+ 'Dec 25'!CC16 +'Jan 26'!CC16+'Feb 26'!CC16+'March 26'!CC16+'April 26'!CC16+'May 26'!CC16+'June 26'!CC16 -> 0 | CF16: {=SUMPRODUCT(--(UPPER($F$2:$CE$2)="NET NEW"),$F16:$CE16)} -> 0 | CG16: =SUMIF($F$2:$CE$2,"Enhance Existing",$F16:$CE16) -> 0 | CH16: =SUMIF($F$2:$CE$2,"Maintenance",$F16:$CE16) -> 1080
A17: QA | B17: Contractor | C17: Jackie Zweck | D17: 95 | F17: ='July 25'!D17 + 'August 25'!D17 +'Sept 25'!D17 + 'Oct 25'!D17 + 'Nov 25'!D17+ 'Dec 25'!D17 +'Jan 26'!D17+'Feb 26'!D17+'March 26'!D17+'April 26'!D17+'May 26'!D17+'June 26'!D17 -> 0 | G17: ='July 25'!E17 + 'August 25'!E17 +'Sept 25'!E17 + 'Oct 25'!E17 + 'Nov 25'!E17+ 'Dec 25'!E17 +'Jan 26'!E17+'Feb 26'!E17+'March 26'!E17+'April 26'!E17+'May 26'!E17+'June 26'!E17 -> 0 | H17: ='July 25'!F17 + 'August 25'!F17 +'Sept 25'!F17 + 'Oct 25'!F17 + 'Nov 25'!F17+ 'Dec 25'!F17 +'Jan 26'!F17+'Feb 26'!F17+'March 26'!F17+'April 26'!F17+'May 26'!F17+'June 26'!F17 -> 0 | I17: ='July 25'!G17 + 'August 25'!G17 +'Sept 25'!G17 + 'Oct 25'!G17 + 'Nov 25'!G17+ 'Dec 25'!G17 +'Jan 26'!G17+'Feb 26'!G17+'March 26'!G17+'April 26'!G17+'May 26'!G17+'June 26'!G17 -> 900 | J17: ='July 25'!H17 + 'August 25'!H17 +'Sept 25'!H17 + 'Oct 25'!H17 + 'Nov 25'!H17+ 'Dec 25'!H17 +'Jan 26'!H17+'Feb 26'!H17+'March 26'!H17+'April 26'!H17+'May 26'!H17+'June 26'!H17 -> 0 | K17: ='July 25'!I17 + 'August 25'!I17 +'Sept 25'!I17 + 'Oct 25'!I17 + 'Nov 25'!I17+ 'Dec 25'!I17 +'Jan 26'!I17+'Feb 26'!I17+'March 26'!I17+'April 26'!I17+'May 26'!I17+'June 26'!I17 -> 400 | L17: ='July 25'!J17 + 'August 25'!J17 +'Sept 25'!J17 + 'Oct 25'!J17 + 'Nov 25'!J17+ 'Dec 25'!J17 +'Jan 26'!J17+'Feb 26'!J17+'March 26'!J17+'April 26'!J17+'May 26'!J17+'June 26'!J17 -> 0 | M17: ='July 25'!K17 + 'August 25'!K17 +'Sept 25'!K17 + 'Oct 25'!K17 + 'Nov 25'!K17+ 'Dec 25'!K17 +'Jan 26'!K17+'Feb 26'!K17+'March 26'!K17+'April 26'!K17+'May 26'!K17+'June 26'!K17 -> 0 | ... CE17: ='July 25'!CC17 + 'August 25'!CC17 +'Sept 25'!CC17 + 'Oct 25'!CC17 + 'Nov 25'!CC17+ 'Dec 25'!CC17 +'Jan 26'!CC17+'Feb 26'!CC17+'March 26'!CC17+'April 26'!CC17+'May 26'!CC17+'June 26'!CC17 -> 0 | CF17: {=SUMPRODUCT(--(UPPER($F$2:$CE$2)="NET NEW"),$F17:$CE17)} -> 900 | CG17: =SUMIF($F$2:$CE$2,"Enhance Existing",$F17:$CE17) -> 0 | CH17: =SUMIF($F$2:$CE$2,"Maintenance",$F17:$CE17) -> 640
A18: Dev | B18: Contractor | C18: Thanuja Bachala | D18: 65 | F18: ='July 25'!D18 + 'August 25'!D18 +'Sept 25'!D18 + 'Oct 25'!D18 + 'Nov 25'!D18+ 'Dec 25'!D18 +'Jan 26'!D18+'Feb 26'!D18+'March 26'!D18+'April 26'!D18+'May 26'!D18+'June 26'!D18 -> 0 | G18: ='July 25'!E18 + 'August 25'!E18 +'Sept 25'!E18 + 'Oct 25'!E18 + 'Nov 25'!E18+ 'Dec 25'!E18 +'Jan 26'!E18+'Feb 26'!E18+'March 26'!E18+'April 26'!E18+'May 26'!E18+'June 26'!E18 -> 0 | H18: ='July 25'!F18 + 'August 25'!F18 +'Sept 25'!F18 + 'Oct 25'!F18 + 'Nov 25'!F18+ 'Dec 25'!F18 +'Jan 26'!F18+'Feb 26'!F18+'March 26'!F18+'April 26'!F18+'May 26'!F18+'June 26'!F18 -> 0 | I18: ='July 25'!G18 + 'August 25'!G18 +'Sept 25'!G18 + 'Oct 25'!G18 + 'Nov 25'!G18+ 'Dec 25'!G18 +'Jan 26'!G18+'Feb 26'!G18+'March 26'!G18+'April 26'!G18+'May 26'!G18+'June 26'!G18 -> 920 | J18: ='July 25'!H18 + 'August 25'!H18 +'Sept 25'!H18 + 'Oct 25'!H18 + 'Nov 25'!H18+ 'Dec 25'!H18 +'Jan 26'!H18+'Feb 26'!H18+'March 26'!H18+'April 26'!H18+'May 26'!H18+'June 26'!H18 -> 0 | K18: ='July 25'!I18 + 'August 25'!I18 +'Sept 25'!I18 + 'Oct 25'!I18 + 'Nov 25'!I18+ 'Dec 25'!I18 +'Jan 26'!I18+'Feb 26'!I18+'March 26'!I18+'April 26'!I18+'May 26'!I18+'June 26'!I18 -> 400 | L18: ='July 25'!J18 + 'August 25'!J18 +'Sept 25'!J18 + 'Oct 25'!J18 + 'Nov 25'!J18+ 'Dec 25'!J18 +'Jan 26'!J18+'Feb 26'!J18+'March 26'!J18+'April 26'!J18+'May 26'!J18+'June 26'!J18 -> 0 | M18: ='July 25'!K18 + 'August 25'!K18 +'Sept 25'!K18 + 'Oct 25'!K18 + 'Nov 25'!K18+ 'Dec 25'!K18 +'Jan 26'!K18+'Feb 26'!K18+'March 26'!K18+'April 26'!K18+'May 26'!K18+'June 26'!K18 -> 0 | ... CE18: ='July 25'!CC18 + 'August 25'!CC18 +'Sept 25'!CC18 + 'Oct 25'!CC18 + 'Nov 25'!CC18+ 'Dec 25'!CC18 +'Jan 26'!CC18+'Feb 26'!CC18+'March 26'!CC18+'April 26'!CC18+'May 26'!CC18+'June 26'!CC18 -> 0 | CF18: {=SUMPRODUCT(--(UPPER($F$2:$CE$2)="NET NEW"),$F18:$CE18)} -> 920 | CG18: =SUMIF($F$2:$CE$2,"Enhance Existing",$F18:$CE18) -> 0 | CH18: =SUMIF($F$2:$CE$2,"Maintenance",$F18:$CE18) -> 620
A19: QA | B19: Contractor | C19: Neeharika Gadela | D19: 79 | F19: ='July 25'!D19 + 'August 25'!D19 +'Sept 25'!D19 + 'Oct 25'!D19 + 'Nov 25'!D19+ 'Dec 25'!D19 +'Jan 26'!D19+'Feb 26'!D19+'March 26'!D19+'April 26'!D19+'May 26'!D19+'June 26'!D19 -> 30 | G19: ='July 25'!E19 + 'August 25'!E19 +'Sept 25'!E19 + 'Oct 25'!E19 + 'Nov 25'!E19+ 'Dec 25'!E19 +'Jan 26'!E19+'Feb 26'!E19+'March 26'!E19+'April 26'!E19+'May 26'!E19+'June 26'!E19 -> 0 | H19: ='July 25'!F19 + 'August 25'!F19 +'Sept 25'!F19 + 'Oct 25'!F19 + 'Nov 25'!F19+ 'Dec 25'!F19 +'Jan 26'!F19+'Feb 26'!F19+'March 26'!F19+'April 26'!F19+'May 26'!F19+'June 26'!F19 -> 80 | I19: ='July 25'!G19 + 'August 25'!G19 +'Sept 25'!G19 + 'Oct 25'!G19 + 'Nov 25'!G19+ 'Dec 25'!G19 +'Jan 26'!G19+'Feb 26'!G19+'March 26'!G19+'April 26'!G19+'May 26'!G19+'June 26'!G19 -> 0 | J19: ='July 25'!H19 + 'August 25'!H19 +'Sept 25'!H19 + 'Oct 25'!H19 + 'Nov 25'!H19+ 'Dec 25'!H19 +'Jan 26'!H19+'Feb 26'!H19+'March 26'!H19+'April 26'!H19+'May 26'!H19+'June 26'!H19 -> 0 | K19: ='July 25'!I19 + 'August 25'!I19 +'Sept 25'!I19 + 'Oct 25'!I19 + 'Nov 25'!I19+ 'Dec 25'!I19 +'Jan 26'!I19+'Feb 26'!I19+'March 26'!I19+'April 26'!I19+'May 26'!I19+'June 26'!I19 -> 0 | L19: ='July 25'!J19 + 'August 25'!J19 +'Sept 25'!J19 + 'Oct 25'!J19 + 'Nov 25'!J19+ 'Dec 25'!J19 +'Jan 26'!J19+'Feb 26'!J19+'March 26'!J19+'April 26'!J19+'May 26'!J19+'June 26'!J19 -> 0 | M19: ='July 25'!K19 + 'August 25'!K19 +'Sept 25'!K19 + 'Oct 25'!K19 + 'Nov 25'!K19+ 'Dec 25'!K19 +'Jan 26'!K19+'Feb 26'!K19+'March 26'!K19+'April 26'!K19+'May 26'!K19+'June 26'!K19 -> 0 | ... CE19: ='July 25'!CC19 + 'August 25'!CC19 +'Sept 25'!CC19 + 'Oct 25'!CC19 + 'Nov 25'!CC19+ 'Dec 25'!CC19 +'Jan 26'!CC19+'Feb 26'!CC19+'March 26'!CC19+'April 26'!CC19+'May 26'!CC19+'June 26'!CC19 -> 0 | CF19: {=SUMPRODUCT(--(UPPER($F$2:$CE$2)="NET NEW"),$F19:$CE19)} -> 30 | CG19: =SUMIF($F$2:$CE$2,"Enhance Existing",$F19:$CE19) -> 20 | CH19: =SUMIF($F$2:$CE$2,"Maintenance",$F19:$CE19) -> 1380
A20: QA | B20: Contractor | C20: Akhil Musani | D20: 80 | F20: ='July 25'!D20 + 'August 25'!D20 +'Sept 25'!D20 + 'Oct 25'!D20 + 'Nov 25'!D20+ 'Dec 25'!D20 +'Jan 26'!D20+'Feb 26'!D20+'March 26'!D20+'April 26'!D20+'May 26'!D20+'June 26'!D20 -> 990 | G20: ='July 25'!E20 + 'August 25'!E20 +'Sept 25'!E20 + 'Oct 25'!E20 + 'Nov 25'!E20+ 'Dec 25'!E20 +'Jan 26'!E20+'Feb 26'!E20+'March 26'!E20+'April 26'!E20+'May 26'!E20+'June 26'!E20 -> 0 | H20: ='July 25'!F20 + 'August 25'!F20 +'Sept 25'!F20 + 'Oct 25'!F20 + 'Nov 25'!F20+ 'Dec 25'!F20 +'Jan 26'!F20+'Feb 26'!F20+'March 26'!F20+'April 26'!F20+'May 26'!F20+'June 26'!F20 -> 170 | I20: ='July 25'!G20 + 'August 25'!G20 +'Sept 25'!G20 + 'Oct 25'!G20 + 'Nov 25'!G20+ 'Dec 25'!G20 +'Jan 26'!G20+'Feb 26'!G20+'March 26'!G20+'April 26'!G20+'May 26'!G20+'June 26'!G20 -> 0 | J20: ='July 25'!H20 + 'August 25'!H20 +'Sept 25'!H20 + 'Oct 25'!H20 + 'Nov 25'!H20+ 'Dec 25'!H20 +'Jan 26'!H20+'Feb 26'!H20+'March 26'!H20+'April 26'!H20+'May 26'!H20+'June 26'!H20 -> 0 | K20: ='July 25'!I20 + 'August 25'!I20 +'Sept 25'!I20 + 'Oct 25'!I20 + 'Nov 25'!I20+ 'Dec 25'!I20 +'Jan 26'!I20+'Feb 26'!I20+'March 26'!I20+'April 26'!I20+'May 26'!I20+'June 26'!I20 -> 0 | L20: ='July 25'!J20 + 'August 25'!J20 +'Sept 25'!J20 + 'Oct 25'!J20 + 'Nov 25'!J20+ 'Dec 25'!J20 +'Jan 26'!J20+'Feb 26'!J20+'March 26'!J20+'April 26'!J20+'May 26'!J20+'June 26'!J20 -> 0 | M20: ='July 25'!K20 + 'August 25'!K20 +'Sept 25'!K20 + 'Oct 25'!K20 + 'Nov 25'!K20+ 'Dec 25'!K20 +'Jan 26'!K20+'Feb 26'!K20+'March 26'!K20+'April 26'!K20+'May 26'!K20+'June 26'!K20 -> 0 | ... CE20: ='July 25'!CC20 + 'August 25'!CC20 +'Sept 25'!CC20 + 'Oct 25'!CC20 + 'Nov 25'!CC20+ 'Dec 25'!CC20 +'Jan 26'!CC20+'Feb 26'!CC20+'March 26'!CC20+'April 26'!CC20+'May 26'!CC20+'June 26'!CC20 -> 0 | CF20: {=SUMPRODUCT(--(UPPER($F$2:$CE$2)="NET NEW"),$F20:$CE20)} -> 990 | CG20: =SUMIF($F$2:$CE$2,"Enhance Existing",$F20:$CE20) -> 50 | CH20: =SUMIF($F$2:$CE$2,"Maintenance",$F20:$CE20) -> 400
A21: Product | B21: Contractor | C21: Eunice Jallah | D21: 110 | F21: ='July 25'!D21 + 'August 25'!D21 +'Sept 25'!D21 + 'Oct 25'!D21 + 'Nov 25'!D21+ 'Dec 25'!D21 +'Jan 26'!D21+'Feb 26'!D21+'March 26'!D21+'April 26'!D21+'May 26'!D21+'June 26'!D21 -> 0 | G21: ='July 25'!E21 + 'August 25'!E21 +'Sept 25'!E21 + 'Oct 25'!E21 + 'Nov 25'!E21+ 'Dec 25'!E21 +'Jan 26'!E21+'Feb 26'!E21+'March 26'!E21+'April 26'!E21+'May 26'!E21+'June 26'!E21 -> 0 | H21: ='July 25'!F21 + 'August 25'!F21 +'Sept 25'!F21 + 'Oct 25'!F21 + 'Nov 25'!F21+ 'Dec 25'!F21 +'Jan 26'!F21+'Feb 26'!F21+'March 26'!F21+'April 26'!F21+'May 26'!F21+'June 26'!F21 -> 0 | I21: ='July 25'!G21 + 'August 25'!G21 +'Sept 25'!G21 + 'Oct 25'!G21 + 'Nov 25'!G21+ 'Dec 25'!G21 +'Jan 26'!G21+'Feb 26'!G21+'March 26'!G21+'April 26'!G21+'May 26'!G21+'June 26'!G21 -> 0 | J21: ='July 25'!H21 + 'August 25'!H21 +'Sept 25'!H21 + 'Oct 25'!H21 + 'Nov 25'!H21+ 'Dec 25'!H21 +'Jan 26'!H21+'Feb 26'!H21+'March 26'!H21+'April 26'!H21+'May 26'!H21+'June 26'!H21 -> 0 | K21: ='July 25'!I21 + 'August 25'!I21 +'Sept 25'!I21 + 'Oct 25'!I21 + 'Nov 25'!I21+ 'Dec 25'!I21 +'Jan 26'!I21+'Feb 26'!I21+'March 26'!I21+'April 26'!I21+'May 26'!I21+'June 26'!I21 -> 0 | L21: ='July 25'!J21 + 'August 25'!J21 +'Sept 25'!J21 + 'Oct 25'!J21 + 'Nov 25'!J21+ 'Dec 25'!J21 +'Jan 26'!J21+'Feb 26'!J21+'March 26'!J21+'April 26'!J21+'May 26'!J21+'June 26'!J21 -> 0 | M21: ='July 25'!K21 + 'August 25'!K21 +'Sept 25'!K21 + 'Oct 25'!K21 + 'Nov 25'!K21+ 'Dec 25'!K21 +'Jan 26'!K21+'Feb 26'!K21+'March 26'!K21+'April 26'!K21+'May 26'!K21+'June 26'!K21 -> 0 | ... CE21: ='July 25'!CC21 + 'August 25'!CC21 +'Sept 25'!CC21 + 'Oct 25'!CC21 + 'Nov 25'!CC21+ 'Dec 25'!CC21 +'Jan 26'!CC21+'Feb 26'!CC21+'March 26'!CC21+'April 26'!CC21+'May 26'!CC21+'June 26'!CC21 -> 0 | CF21: {=SUMPRODUCT(--(UPPER($F$2:$CE$2)="NET NEW"),$F21:$CE21)} -> 0 | CG21: =SUMIF($F$2:$CE$2,"Enhance Existing",$F21:$CE21) -> 250 | CH21: =SUMIF($F$2:$CE$2,"Maintenance",$F21:$CE21) -> 1090
A22: Product | B22: Contractor | C22: Meera Mehta | D22: 110 | F22: ='July 25'!D22 + 'August 25'!D22 +'Sept 25'!D22 + 'Oct 25'!D22 + 'Nov 25'!D22+ 'Dec 25'!D22 +'Jan 26'!D22+'Feb 26'!D22+'March 26'!D22+'April 26'!D22+'May 26'!D22+'June 26'!D22 -> 460 | G22: ='July 25'!E22 + 'August 25'!E22 +'Sept 25'!E22 + 'Oct 25'!E22 + 'Nov 25'!E22+ 'Dec 25'!E22 +'Jan 26'!E22+'Feb 26'!E22+'March 26'!E22+'April 26'!E22+'May 26'!E22+'June 26'!E22 -> 0 | H22: ='July 25'!F22 + 'August 25'!F22 +'Sept 25'!F22 + 'Oct 25'!F22 + 'Nov 25'!F22+ 'Dec 25'!F22 +'Jan 26'!F22+'Feb 26'!F22+'March 26'!F22+'April 26'!F22+'May 26'!F22+'June 26'!F22 -> 0 | I22: ='July 25'!G22 + 'August 25'!G22 +'Sept 25'!G22 + 'Oct 25'!G22 + 'Nov 25'!G22+ 'Dec 25'!G22 +'Jan 26'!G22+'Feb 26'!G22+'March 26'!G22+'April 26'!G22+'May 26'!G22+'June 26'!G22 -> 0 | J22: ='July 25'!H22 + 'August 25'!H22 +'Sept 25'!H22 + 'Oct 25'!H22 + 'Nov 25'!H22+ 'Dec 25'!H22 +'Jan 26'!H22+'Feb 26'!H22+'March 26'!H22+'April 26'!H22+'May 26'!H22+'June 26'!H22 -> 0 | K22: ='July 25'!I22 + 'August 25'!I22 +'Sept 25'!I22 + 'Oct 25'!I22 + 'Nov 25'!I22+ 'Dec 25'!I22 +'Jan 26'!I22+'Feb 26'!I22+'March 26'!I22+'April 26'!I22+'May 26'!I22+'June 26'!I22 -> 0 | L22: ='July 25'!J22 + 'August 25'!J22 +'Sept 25'!J22 + 'Oct 25'!J22 + 'Nov 25'!J22+ 'Dec 25'!J22 +'Jan 26'!J22+'Feb 26'!J22+'March 26'!J22+'April 26'!J22+'May 26'!J22+'June 26'!J22 -> 0 | M22: ='July 25'!K22 + 'August 25'!K22 +'Sept 25'!K22 + 'Oct 25'!K22 + 'Nov 25'!K22+ 'Dec 25'!K22 +'Jan 26'!K22+'Feb 26'!K22+'March 26'!K22+'April 26'!K22+'May 26'!K22+'June 26'!K22 -> 0 | ... CE22: ='July 25'!CC22 + 'August 25'!CC22 +'Sept 25'!CC22 + 'Oct 25'!CC22 + 'Nov 25'!CC22+ 'Dec 25'!CC22 +'Jan 26'!CC22+'Feb 26'!CC22+'March 26'!CC22+'April 26'!CC22+'May 26'!CC22+'June 26'!CC22 -> 0 | CF22: {=SUMPRODUCT(--(UPPER($F$2:$CE$2)="NET NEW"),$F22:$CE22)} -> 460 | CG22: =SUMIF($F$2:$CE$2,"Enhance Existing",$F22:$CE22) -> 610 | CH22: =SUMIF($F$2:$CE$2,"Maintenance",$F22:$CE22) -> 390
A23: Product | B23: Contractor | C23: Rojina Thapa | D23: 70 | F23: ='July 25'!D23 + 'August 25'!D23 +'Sept 25'!D23 + 'Oct 25'!D23 + 'Nov 25'!D23+ 'Dec 25'!D23 +'Jan 26'!D23+'Feb 26'!D23+'March 26'!D23+'April 26'!D23+'May 26'!D23+'June 26'!D23 -> 0 | G23: ='July 25'!E23 + 'August 25'!E23 +'Sept 25'!E23 + 'Oct 25'!E23 + 'Nov 25'!E23+ 'Dec 25'!E23 +'Jan 26'!E23+'Feb 26'!E23+'March 26'!E23+'April 26'!E23+'May 26'!E23+'June 26'!E23 -> 0 | H23: ='July 25'!F23 + 'August 25'!F23 +'Sept 25'!F23 + 'Oct 25'!F23 + 'Nov 25'!F23+ 'Dec 25'!F23 +'Jan 26'!F23+'Feb 26'!F23+'March 26'!F23+'April 26'!F23+'May 26'!F23+'June 26'!F23 -> 0 | I23: ='July 25'!G23 + 'August 25'!G23 +'Sept 25'!G23 + 'Oct 25'!G23 + 'Nov 25'!G23+ 'Dec 25'!G23 +'Jan 26'!G23+'Feb 26'!G23+'March 26'!G23+'April 26'!G23+'May 26'!G23+'June 26'!G23 -> 0 | J23: ='July 25'!H23 + 'August 25'!H23 +'Sept 25'!H23 + 'Oct 25'!H23 + 'Nov 25'!H23+ 'Dec 25'!H23 +'Jan 26'!H23+'Feb 26'!H23+'March 26'!H23+'April 26'!H23+'May 26'!H23+'June 26'!H23 -> 0 | K23: ='July 25'!I23 + 'August 25'!I23 +'Sept 25'!I23 + 'Oct 25'!I23 + 'Nov 25'!I23+ 'Dec 25'!I23 +'Jan 26'!I23+'Feb 26'!I23+'March 26'!I23+'April 26'!I23+'May 26'!I23+'June 26'!I23 -> 0 | L23: ='July 25'!J23 + 'August 25'!J23 +'Sept 25'!J23 + 'Oct 25'!J23 + 'Nov 25'!J23+ 'Dec 25'!J23 +'Jan 26'!J23+'Feb 26'!J23+'March 26'!J23+'April 26'!J23+'May 26'!J23+'June 26'!J23 -> 0 | M23: ='July 25'!K23 + 'August 25'!K23 +'Sept 25'!K23 + 'Oct 25'!K23 + 'Nov 25'!K23+ 'Dec 25'!K23 +'Jan 26'!K23+'Feb 26'!K23+'March 26'!K23+'April 26'!K23+'May 26'!K23+'June 26'!K23 -> 0 | ... CE23: ='July 25'!CC23 + 'August 25'!CC23 +'Sept 25'!CC23 + 'Oct 25'!CC23 + 'Nov 25'!CC23+ 'Dec 25'!CC23 +'Jan 26'!CC23+'Feb 26'!CC23+'March 26'!CC23+'April 26'!CC23+'May 26'!CC23+'June 26'!CC23 -> 85 | CF23: {=SUMPRODUCT(--(UPPER($F$2:$CE$2)="NET NEW"),$F23:$CE23)} -> 160 | CG23: =SUMIF($F$2:$CE$2,"Enhance Existing",$F23:$CE23) -> 0 | CH23: =SUMIF($F$2:$CE$2,"Maintenance",$F23:$CE23) -> 1205
... A25: Product | B25: Contractor | C25: Catherine Horton | D25: 85 | F25: ='July 25'!D25 + 'August 25'!D25 +'Sept 25'!D25 + 'Oct 25'!D25 + 'Nov 25'!D25+ 'Dec 25'!D25 +'Jan 26'!D25+'Feb 26'!D25+'March 26'!D25+'April 26'!D25+'May 26'!D25+'June 26'!D25 -> 0 | G25: ='July 25'!E25 + 'August 25'!E25 +'Sept 25'!E25 + 'Oct 25'!E25 + 'Nov 25'!E25+ 'Dec 25'!E25 +'Jan 26'!E25+'Feb 26'!E25+'March 26'!E25+'April 26'!E25+'May 26'!E25+'June 26'!E25 -> 0 | H25: ='July 25'!F25 + 'August 25'!F25 +'Sept 25'!F25 + 'Oct 25'!F25 + 'Nov 25'!F25+ 'Dec 25'!F25 +'Jan 26'!F25+'Feb 26'!F25+'March 26'!F25+'April 26'!F25+'May 26'!F25+'June 26'!F25 -> 0 | I25: ='July 25'!G25 + 'August 25'!G25 +'Sept 25'!G25 + 'Oct 25'!G25 + 'Nov 25'!G25+ 'Dec 25'!G25 +'Jan 26'!G25+'Feb 26'!G25+'March 26'!G25+'April 26'!G25+'May 26'!G25+'June 26'!G25 -> 0 | J25: ='July 25'!H25 + 'August 25'!H25 +'Sept 25'!H25 + 'Oct 25'!H25 + 'Nov 25'!H25+ 'Dec 25'!H25 +'Jan 26'!H25+'Feb 26'!H25+'March 26'!H25+'April 26'!H25+'May 26'!H25+'June 26'!H25 -> 0 | K25: ='July 25'!I25 + 'August 25'!I25 +'Sept 25'!I25 + 'Oct 25'!I25 + 'Nov 25'!I25+ 'Dec 25'!I25 +'Jan 26'!I25+'Feb 26'!I25+'March 26'!I25+'April 26'!I25+'May 26'!I25+'June 26'!I25 -> 0 | L25: ='July 25'!J25 + 'August 25'!J25 +'Sept 25'!J25 + 'Oct 25'!J25 + 'Nov 25'!J25+ 'Dec 25'!J25 +'Jan 26'!J25+'Feb 26'!J25+'March 26'!J25+'April 26'!J25+'May 26'!J25+'June 26'!J25 -> 0 | M25: ='July 25'!K25 + 'August 25'!K25 +'Sept 25'!K25 + 'Oct 25'!K25 + 'Nov 25'!K25+ 'Dec 25'!K25 +'Jan 26'!K25+'Feb 26'!K25+'March 26'!K25+'April 26'!K25+'May 26'!K25+'June 26'!K25 -> 0 | ... CE25: ='July 25'!CC25 + 'August 25'!CC25 +'Sept 25'!CC25 + 'Oct 25'!CC25 + 'Nov 25'!CC25+ 'Dec 25'!CC25 +'Jan 26'!CC25+'Feb 26'!CC25+'March 26'!CC25+'April 26'!CC25+'May 26'!CC25+'June 26'!CC25 -> 0 | CF25: {=SUMPRODUCT(--(UPPER($F$2:$CE$2)="NET NEW"),$F25:$CE25)} -> 0 | CG25: =SUMIF($F$2:$CE$2,"Enhance Existing",$F25:$CE25) -> 0 | CH25: =SUMIF($F$2:$CE$2,"Maintenance",$F25:$CE25) -> 1440
A26: Product | B26: FTE | C26: Latha Ramasamy | F26: ='July 25'!D26 + 'August 25'!D26 +'Sept 25'!D26 + 'Oct 25'!D26 + 'Nov 25'!D26+ 'Dec 25'!D26 +'Jan 26'!D26+'Feb 26'!D26+'March 26'!D26+'April 26'!D26+'May 26'!D26+'June 26'!D26 -> 0 | G26: ='July 25'!E26 + 'August 25'!E26 +'Sept 25'!E26 + 'Oct 25'!E26 + 'Nov 25'!E26+ 'Dec 25'!E26 +'Jan 26'!E26+'Feb 26'!E26+'March 26'!E26+'April 26'!E26+'May 26'!E26+'June 26'!E26 -> 0 | H26: ='July 25'!F26 + 'August 25'!F26 +'Sept 25'!F26 + 'Oct 25'!F26 + 'Nov 25'!F26+ 'Dec 25'!F26 +'Jan 26'!F26+'Feb 26'!F26+'March 26'!F26+'April 26'!F26+'May 26'!F26+'June 26'!F26 -> 0 | I26: ='July 25'!G26 + 'August 25'!G26 +'Sept 25'!G26 + 'Oct 25'!G26 + 'Nov 25'!G26+ 'Dec 25'!G26 +'Jan 26'!G26+'Feb 26'!G26+'March 26'!G26+'April 26'!G26+'May 26'!G26+'June 26'!G26 -> 1000 | J26: ='July 25'!H26 + 'August 25'!H26 +'Sept 25'!H26 + 'Oct 25'!H26 + 'Nov 25'!H26+ 'Dec 25'!H26 +'Jan 26'!H26+'Feb 26'!H26+'March 26'!H26+'April 26'!H26+'May 26'!H26+'June 26'!H26 -> 0 | K26: ='July 25'!I26 + 'August 25'!I26 +'Sept 25'!I26 + 'Oct 25'!I26 + 'Nov 25'!I26+ 'Dec 25'!I26 +'Jan 26'!I26+'Feb 26'!I26+'March 26'!I26+'April 26'!I26+'May 26'!I26+'June 26'!I26 -> 360 | L26: ='July 25'!J26 + 'August 25'!J26 +'Sept 25'!J26 + 'Oct 25'!J26 + 'Nov 25'!J26+ 'Dec 25'!J26 +'Jan 26'!J26+'Feb 26'!J26+'March 26'!J26+'April 26'!J26+'May 26'!J26+'June 26'!J26 -> 0 | M26: ='July 25'!K26 + 'August 25'!K26 +'Sept 25'!K26 + 'Oct 25'!K26 + 'Nov 25'!K26+ 'Dec 25'!K26 +'Jan 26'!K26+'Feb 26'!K26+'March 26'!K26+'April 26'!K26+'May 26'!K26+'June 26'!K26 -> 0 | ... CE26: ='July 25'!CC26 + 'August 25'!CC26 +'Sept 25'!CC26 + 'Oct 25'!CC26 + 'Nov 25'!CC26+ 'Dec 25'!CC26 +'Jan 26'!CC26+'Feb 26'!CC26+'March 26'!CC26+'April 26'!CC26+'May 26'!CC26+'June 26'!CC26 -> 0 | CF26: {=SUMPRODUCT(--(UPPER($F$2:$CE$2)="NET NEW"),$F26:$CE26)} -> 1000 | CG26: =SUMIF($F$2:$CE$2,"Enhance Existing",$F26:$CE26) -> 0 | CH26: =SUMIF($F$2:$CE$2,"Maintenance",$F26:$CE26) -> 440
A27: Sr. Dev | B27: Contractor | C27: Claire Smith-Edwards | D27: 79 | F27: ='July 25'!D27 + 'August 25'!D27 +'Sept 25'!D27 + 'Oct 25'!D27 + 'Nov 25'!D27+ 'Dec 25'!D27 +'Jan 26'!D27+'Feb 26'!D27+'March 26'!D27+'April 26'!D27+'May 26'!D27+'June 26'!D27 -> 1440 | G27: ='July 25'!E27 + 'August 25'!E27 +'Sept 25'!E27 + 'Oct 25'!E27 + 'Nov 25'!E27+ 'Dec 25'!E27 +'Jan 26'!E27+'Feb 26'!E27+'March 26'!E27+'April 26'!E27+'May 26'!E27+'June 26'!E27 -> 0 | H27: ='July 25'!F27 + 'August 25'!F27 +'Sept 25'!F27 + 'Oct 25'!F27 + 'Nov 25'!F27+ 'Dec 25'!F27 +'Jan 26'!F27+'Feb 26'!F27+'March 26'!F27+'April 26'!F27+'May 26'!F27+'June 26'!F27 -> 0 | I27: ='July 25'!G27 + 'August 25'!G27 +'Sept 25'!G27 + 'Oct 25'!G27 + 'Nov 25'!G27+ 'Dec 25'!G27 +'Jan 26'!G27+'Feb 26'!G27+'March 26'!G27+'April 26'!G27+'May 26'!G27+'June 26'!G27 -> 0 | J27: ='July 25'!H27 + 'August 25'!H27 +'Sept 25'!H27 + 'Oct 25'!H27 + 'Nov 25'!H27+ 'Dec 25'!H27 +'Jan 26'!H27+'Feb 26'!H27+'March 26'!H27+'April 26'!H27+'May 26'!H27+'June 26'!H27 -> 0 | K27: ='July 25'!I27 + 'August 25'!I27 +'Sept 25'!I27 + 'Oct 25'!I27 + 'Nov 25'!I27+ 'Dec 25'!I27 +'Jan 26'!I27+'Feb 26'!I27+'March 26'!I27+'April 26'!I27+'May 26'!I27+'June 26'!I27 -> 0 | L27: ='July 25'!J27 + 'August 25'!J27 +'Sept 25'!J27 + 'Oct 25'!J27 + 'Nov 25'!J27+ 'Dec 25'!J27 +'Jan 26'!J27+'Feb 26'!J27+'March 26'!J27+'April 26'!J27+'May 26'!J27+'June 26'!J27 -> 0 | M27: ='July 25'!K27 + 'August 25'!K27 +'Sept 25'!K27 + 'Oct 25'!K27 + 'Nov 25'!K27+ 'Dec 25'!K27 +'Jan 26'!K27+'Feb 26'!K27+'March 26'!K27+'April 26'!K27+'May 26'!K27+'June 26'!K27 -> 0 | ... CE27: ='July 25'!CC27 + 'August 25'!CC27 +'Sept 25'!CC27 + 'Oct 25'!CC27 + 'Nov 25'!CC27+ 'Dec 25'!CC27 +'Jan 26'!CC27+'Feb 26'!CC27+'March 26'!CC27+'April 26'!CC27+'May 26'!CC27+'June 26'!CC27 -> 0 | CF27: {=SUMPRODUCT(--(UPPER($F$2:$CE$2)="NET NEW"),$F27:$CE27)} -> 1440 | CG27: =SUMIF($F$2:$CE$2,"Enhance Existing",$F27:$CE27) -> 0 | CH27: =SUMIF($F$2:$CE$2,"Maintenance",$F27:$CE27) -> 0
A28: Dev | B28: Contractor | C28: Vinay Sunkyredi | D28: 88 | F28: ='July 25'!D28 + 'August 25'!D28 +'Sept 25'!D28 + 'Oct 25'!D28 + 'Nov 25'!D28+ 'Dec 25'!D28 +'Jan 26'!D28+'Feb 26'!D28+'March 26'!D28+'April 26'!D28+'May 26'!D28+'June 26'!D28 -> 1000 | G28: ='July 25'!E28 + 'August 25'!E28 +'Sept 25'!E28 + 'Oct 25'!E28 + 'Nov 25'!E28+ 'Dec 25'!E28 +'Jan 26'!E28+'Feb 26'!E28+'March 26'!E28+'April 26'!E28+'May 26'!E28+'June 26'!E28 -> 0 | H28: ='July 25'!F28 + 'August 25'!F28 +'Sept 25'!F28 + 'Oct 25'!F28 + 'Nov 25'!F28+ 'Dec 25'!F28 +'Jan 26'!F28+'Feb 26'!F28+'March 26'!F28+'April 26'!F28+'May 26'!F28+'June 26'!F28 -> 0 | I28: ='July 25'!G28 + 'August 25'!G28 +'Sept 25'!G28 + 'Oct 25'!G28 + 'Nov 25'!G28+ 'Dec 25'!G28 +'Jan 26'!G28+'Feb 26'!G28+'March 26'!G28+'April 26'!G28+'May 26'!G28+'June 26'!G28 -> 0 | J28: ='July 25'!H28 + 'August 25'!H28 +'Sept 25'!H28 + 'Oct 25'!H28 + 'Nov 25'!H28+ 'Dec 25'!H28 +'Jan 26'!H28+'Feb 26'!H28+'March 26'!H28+'April 26'!H28+'May 26'!H28+'June 26'!H28 -> 0 | K28: ='July 25'!I28 + 'August 25'!I28 +'Sept 25'!I28 + 'Oct 25'!I28 + 'Nov 25'!I28+ 'Dec 25'!I28 +'Jan 26'!I28+'Feb 26'!I28+'March 26'!I28+'April 26'!I28+'May 26'!I28+'June 26'!I28 -> 0 | L28: ='July 25'!J28 + 'August 25'!J28 +'Sept 25'!J28 + 'Oct 25'!J28 + 'Nov 25'!J28+ 'Dec 25'!J28 +'Jan 26'!J28+'Feb 26'!J28+'March 26'!J28+'April 26'!J28+'May 26'!J28+'June 26'!J28 -> 0 | M28: ='July 25'!K28 + 'August 25'!K28 +'Sept 25'!K28 + 'Oct 25'!K28 + 'Nov 25'!K28+ 'Dec 25'!K28 +'Jan 26'!K28+'Feb 26'!K28+'March 26'!K28+'April 26'!K28+'May 26'!K28+'June 26'!K28 -> 0 | ... CE28: ='July 25'!CC28 + 'August 25'!CC28 +'Sept 25'!CC28 + 'Oct 25'!CC28 + 'Nov 25'!CC28+ 'Dec 25'!CC28 +'Jan 26'!CC28+'Feb 26'!CC28+'March 26'!CC28+'April 26'!CC28+'May 26'!CC28+'June 26'!CC28 -> 0 | CF28: {=SUMPRODUCT(--(UPPER($F$2:$CE$2)="NET NEW"),$F28:$CE28)} -> 1000 | CG28: =SUMIF($F$2:$CE$2,"Enhance Existing",$F28:$CE28) -> 90 | CH28: =SUMIF($F$2:$CE$2,"Maintenance",$F28:$CE28) -> 350
A29: Dev Ops | B29: Contractor | C29: Gunter | D29: 148.125 | F29: ='July 25'!D29 + 'August 25'!D29 +'Sept 25'!D29 + 'Oct 25'!D29 + 'Nov 25'!D29+ 'Dec 25'!D29 +'Jan 26'!D29+'Feb 26'!D29+'March 26'!D29+'April 26'!D29+'May 26'!D29+'June 26'!D29 -> 0 | G29: ='July 25'!E29 + 'August 25'!E29 +'Sept 25'!E29 + 'Oct 25'!E29 + 'Nov 25'!E29+ 'Dec 25'!E29 +'Jan 26'!E29+'Feb 26'!E29+'March 26'!E29+'April 26'!E29+'May 26'!E29+'June 26'!E29 -> 0 | H29: ='July 25'!F29 + 'August 25'!F29 +'Sept 25'!F29 + 'Oct 25'!F29 + 'Nov 25'!F29+ 'Dec 25'!F29 +'Jan 26'!F29+'Feb 26'!F29+'March 26'!F29+'April 26'!F29+'May 26'!F29+'June 26'!F29 -> 0 | I29: ='July 25'!G29 + 'August 25'!G29 +'Sept 25'!G29 + 'Oct 25'!G29 + 'Nov 25'!G29+ 'Dec 25'!G29 +'Jan 26'!G29+'Feb 26'!G29+'March 26'!G29+'April 26'!G29+'May 26'!G29+'June 26'!G29 -> 0 | J29: ='July 25'!H29 + 'August 25'!H29 +'Sept 25'!H29 + 'Oct 25'!H29 + 'Nov 25'!H29+ 'Dec 25'!H29 +'Jan 26'!H29+'Feb 26'!H29+'March 26'!H29+'April 26'!H29+'May 26'!H29+'June 26'!H29 -> 0 | K29: ='July 25'!I29 + 'August 25'!I29 +'Sept 25'!I29 + 'Oct 25'!I29 + 'Nov 25'!I29+ 'Dec 25'!I29 +'Jan 26'!I29+'Feb 26'!I29+'March 26'!I29+'April 26'!I29+'May 26'!I29+'June 26'!I29 -> 0 | L29: ='July 25'!J29 + 'August 25'!J29 +'Sept 25'!J29 + 'Oct 25'!J29 + 'Nov 25'!J29+ 'Dec 25'!J29 +'Jan 26'!J29+'Feb 26'!J29+'March 26'!J29+'April 26'!J29+'May 26'!J29+'June 26'!J29 -> 0 | M29: ='July 25'!K29 + 'August 25'!K29 +'Sept 25'!K29 + 'Oct 25'!K29 + 'Nov 25'!K29+ 'Dec 25'!K29 +'Jan 26'!K29+'Feb 26'!K29+'March 26'!K29+'April 26'!K29+'May 26'!K29+'June 26'!K29 -> 0 | ... CE29: ='July 25'!CC29 + 'August 25'!CC29 +'Sept 25'!CC29 + 'Oct 25'!CC29 + 'Nov 25'!CC29+ 'Dec 25'!CC29 +'Jan 26'!CC29+'Feb 26'!CC29+'March 26'!CC29+'April 26'!CC29+'May 26'!CC29+'June 26'!CC29 -> 0 | CF29: {=SUMPRODUCT(--(UPPER($F$2:$CE$2)="NET NEW"),$F29:$CE29)} -> 0 | CG29: =SUMIF($F$2:$CE$2,"Enhance Existing",$F29:$CE29) -> 720 | CH29: =SUMIF($F$2:$CE$2,"Maintenance",$F29:$CE29) -> 720
A30: Dev Ops | B30: FTE | C30: Zack | F30: ='July 25'!D30 + 'August 25'!D30 +'Sept 25'!D30 + 'Oct 25'!D30 + 'Nov 25'!D30+ 'Dec 25'!D30 +'Jan 26'!D30+'Feb 26'!D30+'March 26'!D30+'April 26'!D30+'May 26'!D30+'June 26'!D30 -> 0 | G30: ='July 25'!E30 + 'August 25'!E30 +'Sept 25'!E30 + 'Oct 25'!E30 + 'Nov 25'!E30+ 'Dec 25'!E30 +'Jan 26'!E30+'Feb 26'!E30+'March 26'!E30+'April 26'!E30+'May 26'!E30+'June 26'!E30 -> 0 | H30: ='July 25'!F30 + 'August 25'!F30 +'Sept 25'!F30 + 'Oct 25'!F30 + 'Nov 25'!F30+ 'Dec 25'!F30 +'Jan 26'!F30+'Feb 26'!F30+'March 26'!F30+'April 26'!F30+'May 26'!F30+'June 26'!F30 -> 0 | I30: ='July 25'!G30 + 'August 25'!G30 +'Sept 25'!G30 + 'Oct 25'!G30 + 'Nov 25'!G30+ 'Dec 25'!G30 +'Jan 26'!G30+'Feb 26'!G30+'March 26'!G30+'April 26'!G30+'May 26'!G30+'June 26'!G30 -> 0 | J30: ='July 25'!H30 + 'August 25'!H30 +'Sept 25'!H30 + 'Oct 25'!H30 + 'Nov 25'!H30+ 'Dec 25'!H30 +'Jan 26'!H30+'Feb 26'!H30+'March 26'!H30+'April 26'!H30+'May 26'!H30+'June 26'!H30 -> 0 | K30: ='July 25'!I30 + 'August 25'!I30 +'Sept 25'!I30 + 'Oct 25'!I30 + 'Nov 25'!I30+ 'Dec 25'!I30 +'Jan 26'!I30+'Feb 26'!I30+'March 26'!I30+'April 26'!I30+'May 26'!I30+'June 26'!I30 -> 0 | L30: ='July 25'!J30 + 'August 25'!J30 +'Sept 25'!J30 + 'Oct 25'!J30 + 'Nov 25'!J30+ 'Dec 25'!J30 +'Jan 26'!J30+'Feb 26'!J30+'March 26'!J30+'April 26'!J30+'May 26'!J30+'June 26'!J30 -> 0 | M30: ='July 25'!K30 + 'August 25'!K30 +'Sept 25'!K30 + 'Oct 25'!K30 + 'Nov 25'!K30+ 'Dec 25'!K30 +'Jan 26'!K30+'Feb 26'!K30+'March 26'!K30+'April 26'!K30+'May 26'!K30+'June 26'!K30 -> 0 | ... CE30: ='July 25'!CC30 + 'August 25'!CC30 +'Sept 25'!CC30 + 'Oct 25'!CC30 + 'Nov 25'!CC30+ 'Dec 25'!CC30 +'Jan 26'!CC30+'Feb 26'!CC30+'March 26'!CC30+'April 26'!CC30+'May 26'!CC30+'June 26'!CC30 -> 0 | CF30: {=SUMPRODUCT(--(UPPER($F$2:$CE$2)="NET NEW"),$F30:$CE30)} -> 0 | CG30: =SUMIF($F$2:$CE$2,"Enhance Existing",$F30:$CE30) -> 720 | CH30: =SUMIF($F$2:$CE$2,"Maintenance",$F30:$CE30) -> 720
F31: =SUM(F3:F30) -> 6360 | G31: =SUM(G3:G30) -> 0 | H31: =SUM(H3:H30) -> 1668 | I31: =SUM(I3:I30) -> 5700 | J31: =SUM(J3:J30) -> 0 | K31: =SUM(K3:K30) -> 1273 | L31: =SUM(L3:L30) -> 0 | M31: =SUM(M3:M30) -> 0 | ... CH31: =SUM(CH3:CH30) -> 21872

Sheet July 25
C1: =Master!E1 -> Product | D1: =Master!F1 -> SWORD | E1: =Master!G1 -> SWORD | F1: =Master!H1 -> SWORD | G1: =Master!I1 -> TEDS | H1: =Master!J1 -> TEDS | I1: =Master!K1 -> TEDS | J1: =Master!L1 -> SPEAR | ... CH1: =Master!CJ1 -> 0
A2: Role | B2: Contractor Name | C2: =Master!E2 -> 0 | D2: =Master!F2 -> Net New | E2: =Master!G2 -> Enhance Existing | F2: =Master!H2 -> Maintenance | G2: =Master!I2 -> Net New | H2: =Master!J2 -> Enhance Existing | I2: =Master!K2 -> Maintenance | J2: =Master!L2 -> Net New | ... CE2: =Master!CG2 -> Enhance Existing Hours
A3: =Master!A3 -> Sr. Dev | B3: =Master!C3 -> Steven McKee | G3: 120
A4: =Master!A4 -> Dev | B4: =Master!C4 -> Pooja | Z4: 60 | AA4: 60
A5: =Master!A5 -> Sr. Dev | B5: =Master!C5 -> Tony | G5: 120
A6: =Master!A6 -> Dev | B6: =Master!C6 -> Lalitha | R6: 4 | AD6: 12 | BQ6: 8 | BW6: 95 | BZ6: 7
A7: =Master!A7 -> Sr. Dev | B7: =Master!C7 -> Greg Marcum | F7: 8 | I7: 47 | AG7: 14 | AV7: 11 | BB7: 10 | BE7: 2 | BW7: 36 | BZ7: 4
A8: =Master!A8 -> Dev | B8: =Master!C8 -> Simrath | N8: 2 | AD8: 21 | AP8: 23 | AS8: 9 | BH8: 5 | BW8: 55 | CC8: 4
A9: =Master!A9 -> Dev | B9: =Master!C9 -> Sriram | AP9: 18 | AS9: 45 | BW9: 46
A10: =Master!A10 -> Dev | B10: =Master!C10 -> Justin Meshew | N10: 4 | R10: 20 | AD10: 9 | BW10: 4 | BZ10: 42 | CC10: 35
A11: =Master!A11 -> Sr. Dev | B11: =Master!C11 -> Ryan Dailey | BW11: 126
A12: =Master!A12 -> Dev | B12: =Master!C12 -> Dean Bowles | AS12: 2 | BW12: 71
A13: =Master!A13 -> Sr. Dev | B13: =Master!C13 -> Donnie | D13: 100 | F13: 20
A14: =Master!A14 -> Sr. Dev | B14: =Master!C14 -> Mark | D14: 120
A15: =Master!A15 -> Dev | B15: =Master!C15 -> Kasey Goodwin
A16: =Master!A16 -> Sr. Dev | B16: =Master!C16 -> Greg Brethen
A17: =Master!A17 -> QA | B17: =Master!C17 -> Jackie Zweck | G17: 100 | U17: 5 | AG17: 5 | BW17: 10
A18: =Master!A18 -> Dev | B18: =Master!C18 -> Thanuja Bachala | G18: 120
A19: =Master!A19 -> QA | B19: =Master!C19 -> Neeharika Gadela | D19: 20 | BW19: 100
A20: =Master!A20 -> QA | B20: =Master!C20 -> Akhil Musani | D20: 80 | F20: 10 | BW20: 20
A21: =Master!A21 -> Product | B21: =Master!C21 -> Eunice Jallah | BG21: 20 | BW21: 100
A22: =Master!A22 -> Product | B22: =Master!C22 -> Meera Mehta | T22: 40 | U22: 30 | BW22: 50
A23: =Master!A23 -> Product | B23: =Master!C23 -> Rojina Thapa | L23: 75 | AG23: 20 | AS23: 5 | BE23: 5 | BW23: 15
A24: =Master!A24 -> Product | B24: =Master!C24 -> Pankaj Kokate | X24: 20 | AA24: 20 | BW24: 80
A25: =Master!A25 -> Product | B25: =Master!C25 -> Catherine Horton | AM25: 120
A26: =Master!A26 -> Product | B26: =Master!C26 -> Latha Ramasamy | G26: 120
A27: =Master!A27 -> Sr. Dev | B27: =Master!C27 -> Claire Smith-Edwards | D27: 120
A28: =Master!A28 -> Dev | B28: =Master!C28 -> Vinay Sunkyredi | D28: 60 | AA28: 60
A29: =Master!A29 -> Dev Ops | B29: =Master!C29 -> Gunter | BV29: 60 | BW29: 60
A30: =Master!A30 -> Dev Ops | B30: =Master!C30 -> Zack | BV30: 60 | BW30: 60
B31: =Master!C31 -> 0

Sheet August 25
C1: =Master!E1 -> Product | D1: =Master!F1 -> SWORD | E1: =Master!G1 -> SWORD | F1: =Master!H1 -> SWORD | G1: =Master!I1 -> TEDS | H1: =Master!J1 -> TEDS | I1: =Master!K1 -> TEDS | J1: =Master!L1 -> SPEAR | ... DP1: =Master!DR1 -> 0
A2: Role | B2: Contractor Name | C2: =Master!E2 -> 0 | D2: =Master!F2 -> Net New | E2: =Master!G2 -> Enhance Existing | F2: =Master!H2 -> Maintenance | G2: =Master!I2 -> Net New | H2: =Master!J2 -> Enhance Existing | I2: =Master!K2 -> Maintenance | J2: =Master!L2 -> Net New | ... CD2: =Master!CF2 -> Net New Hours
A3: =Master!A3 -> Sr. Dev | B3: =Master!C3 -> Steven McKee | G3: 120
A4: =Master!A4 -> Dev | B4: =Master!C4 -> Pooja | Z4: 60 | AA4: 60
A5: =Master!A5 -> Sr. Dev | B5: =Master!C5 -> Tony | G5: 120
A6: =Master!A6 -> Dev | B6: =Master!C6 -> Lalitha | R6: 8 | AD6: 12 | BQ6: 5 | BW6: 86 | BZ6: 15
A7: =Master!A7 -> Sr. Dev | B7: =Master!C7 -> Greg Marcum | I7: 39 | AG7: 14 | AV7: 20 | BE7: 2 | BW7: 43 | BZ7: 8
A8: =Master!A8 -> Dev | B8: =Master!C8 -> Simrath | AD8: 8 | AP8: 23 | AS8: 3 | BW8: 75 | CC8: 5
A9: =Master!A9 -> Dev | B9: =Master!C9 -> Sriram | AP9: 24 | AS9: 43 | BF9: 8 | BW9: 39
A10: =Master!A10 -> Dev | B10: =Master!C10 -> Justin Meshew | N10: 3 | R10: 14 | AD10: 11 | BW10: 4 | BZ10: 62 | CC10: 20
A11: =Master!A11 -> Sr. Dev | B11: =Master!C11 -> Ryan Dailey | BW11: 114
A12: =Master!A12 -> Dev | B12: =Master!C12 -> Dean Bowles
A13: =Master!A13 -> Sr. Dev | B13: =Master!C13 -> Donnie | D13: 100 | F13: 20
A14: =Master!A14 -> Sr. Dev | B14: =Master!C14 -> Mark | D14: 120
A15: =Master!A15 -> Dev | B15: =Master!C15 -> Kasey Goodwin
A16: =Master!A16 -> Sr. Dev | B16: =Master!C16 -> Greg Brethen
A17: =Master!A17 -> QA | B17: =Master!C17 -> Jackie Zweck | G17: 100 | I17: 100 | BW17: 20
